[2023-08-11T07:57:42.433+0000] {processor.py:157} INFO - Started process (PID=683) to work on /opt/airflow/dags/weather_data_dag.py
[2023-08-11T07:57:42.434+0000] {processor.py:826} INFO - Processing file /opt/airflow/dags/weather_data_dag.py for tasks to queue
[2023-08-11T07:57:42.435+0000] {logging_mixin.py:150} INFO - [2023-08-11T07:57:42.434+0000] {dagbag.py:541} INFO - Filling up the DagBag from /opt/airflow/dags/weather_data_dag.py
[2023-08-11T07:57:42.454+0000] {logging_mixin.py:150} INFO - [2023-08-11T07:57:42.453+0000] {dagbag.py:350} ERROR - Failed to import: /opt/airflow/dags/weather_data_dag.py
Traceback (most recent call last):
  File "/home/airflow/.local/lib/python3.7/site-packages/airflow/models/dagbag.py", line 346, in parse
    loader.exec_module(new_module)
  File "<frozen importlib._bootstrap_external>", line 728, in exec_module
  File "<frozen importlib._bootstrap>", line 219, in _call_with_frames_removed
  File "/opt/airflow/dags/weather_data_dag.py", line 8, in <module>
    WORK_DIR = os.environ["WORK_DIR"]
  File "/usr/local/lib/python3.7/os.py", line 681, in __getitem__
    raise KeyError(key) from None
KeyError: 'WORK_DIR'
[2023-08-11T07:57:42.454+0000] {processor.py:838} WARNING - No viable dags retrieved from /opt/airflow/dags/weather_data_dag.py
[2023-08-11T07:57:42.476+0000] {processor.py:179} INFO - Processing /opt/airflow/dags/weather_data_dag.py took 0.046 seconds
[2023-08-11T07:58:12.501+0000] {processor.py:157} INFO - Started process (PID=749) to work on /opt/airflow/dags/weather_data_dag.py
[2023-08-11T07:58:12.502+0000] {processor.py:826} INFO - Processing file /opt/airflow/dags/weather_data_dag.py for tasks to queue
[2023-08-11T07:58:12.502+0000] {logging_mixin.py:150} INFO - [2023-08-11T07:58:12.502+0000] {dagbag.py:541} INFO - Filling up the DagBag from /opt/airflow/dags/weather_data_dag.py
[2023-08-11T07:58:12.512+0000] {logging_mixin.py:150} INFO - [2023-08-11T07:58:12.511+0000] {dagbag.py:350} ERROR - Failed to import: /opt/airflow/dags/weather_data_dag.py
Traceback (most recent call last):
  File "/home/airflow/.local/lib/python3.7/site-packages/airflow/models/dagbag.py", line 346, in parse
    loader.exec_module(new_module)
  File "<frozen importlib._bootstrap_external>", line 728, in exec_module
  File "<frozen importlib._bootstrap>", line 219, in _call_with_frames_removed
  File "/opt/airflow/dags/weather_data_dag.py", line 8, in <module>
    WORK_DIR = os.environ["WORK_DIR"]
  File "/usr/local/lib/python3.7/os.py", line 681, in __getitem__
    raise KeyError(key) from None
KeyError: 'WORK_DIR'
[2023-08-11T07:58:12.512+0000] {processor.py:838} WARNING - No viable dags retrieved from /opt/airflow/dags/weather_data_dag.py
[2023-08-11T07:58:12.532+0000] {processor.py:179} INFO - Processing /opt/airflow/dags/weather_data_dag.py took 0.034 seconds
[2023-08-11T07:58:42.680+0000] {processor.py:157} INFO - Started process (PID=815) to work on /opt/airflow/dags/weather_data_dag.py
[2023-08-11T07:58:42.681+0000] {processor.py:826} INFO - Processing file /opt/airflow/dags/weather_data_dag.py for tasks to queue
[2023-08-11T07:58:42.682+0000] {logging_mixin.py:150} INFO - [2023-08-11T07:58:42.681+0000] {dagbag.py:541} INFO - Filling up the DagBag from /opt/airflow/dags/weather_data_dag.py
[2023-08-11T07:58:42.690+0000] {logging_mixin.py:150} INFO - [2023-08-11T07:58:42.688+0000] {dagbag.py:350} ERROR - Failed to import: /opt/airflow/dags/weather_data_dag.py
Traceback (most recent call last):
  File "/home/airflow/.local/lib/python3.7/site-packages/airflow/models/dagbag.py", line 346, in parse
    loader.exec_module(new_module)
  File "<frozen importlib._bootstrap_external>", line 728, in exec_module
  File "<frozen importlib._bootstrap>", line 219, in _call_with_frames_removed
  File "/opt/airflow/dags/weather_data_dag.py", line 8, in <module>
    WORK_DIR = os.environ["WORK_DIR"]
  File "/usr/local/lib/python3.7/os.py", line 681, in __getitem__
    raise KeyError(key) from None
KeyError: 'WORK_DIR'
[2023-08-11T07:58:42.691+0000] {processor.py:838} WARNING - No viable dags retrieved from /opt/airflow/dags/weather_data_dag.py
[2023-08-11T07:58:42.711+0000] {processor.py:179} INFO - Processing /opt/airflow/dags/weather_data_dag.py took 0.033 seconds
[2023-08-11T07:59:12.945+0000] {processor.py:157} INFO - Started process (PID=881) to work on /opt/airflow/dags/weather_data_dag.py
[2023-08-11T07:59:12.947+0000] {processor.py:826} INFO - Processing file /opt/airflow/dags/weather_data_dag.py for tasks to queue
[2023-08-11T07:59:12.948+0000] {logging_mixin.py:150} INFO - [2023-08-11T07:59:12.948+0000] {dagbag.py:541} INFO - Filling up the DagBag from /opt/airflow/dags/weather_data_dag.py
[2023-08-11T07:59:12.958+0000] {logging_mixin.py:150} INFO - [2023-08-11T07:59:12.956+0000] {dagbag.py:350} ERROR - Failed to import: /opt/airflow/dags/weather_data_dag.py
Traceback (most recent call last):
  File "/home/airflow/.local/lib/python3.7/site-packages/airflow/models/dagbag.py", line 346, in parse
    loader.exec_module(new_module)
  File "<frozen importlib._bootstrap_external>", line 728, in exec_module
  File "<frozen importlib._bootstrap>", line 219, in _call_with_frames_removed
  File "/opt/airflow/dags/weather_data_dag.py", line 8, in <module>
    WORK_DIR = os.environ["WORK_DIR"]
  File "/usr/local/lib/python3.7/os.py", line 681, in __getitem__
    raise KeyError(key) from None
KeyError: 'WORK_DIR'
[2023-08-11T07:59:12.958+0000] {processor.py:838} WARNING - No viable dags retrieved from /opt/airflow/dags/weather_data_dag.py
[2023-08-11T07:59:13.098+0000] {processor.py:179} INFO - Processing /opt/airflow/dags/weather_data_dag.py took 0.158 seconds
[2023-08-11T07:59:43.584+0000] {processor.py:157} INFO - Started process (PID=947) to work on /opt/airflow/dags/weather_data_dag.py
[2023-08-11T07:59:43.585+0000] {processor.py:826} INFO - Processing file /opt/airflow/dags/weather_data_dag.py for tasks to queue
[2023-08-11T07:59:43.586+0000] {logging_mixin.py:150} INFO - [2023-08-11T07:59:43.585+0000] {dagbag.py:541} INFO - Filling up the DagBag from /opt/airflow/dags/weather_data_dag.py
[2023-08-11T07:59:43.595+0000] {logging_mixin.py:150} INFO - [2023-08-11T07:59:43.593+0000] {dagbag.py:350} ERROR - Failed to import: /opt/airflow/dags/weather_data_dag.py
Traceback (most recent call last):
  File "/home/airflow/.local/lib/python3.7/site-packages/airflow/models/dagbag.py", line 346, in parse
    loader.exec_module(new_module)
  File "<frozen importlib._bootstrap_external>", line 728, in exec_module
  File "<frozen importlib._bootstrap>", line 219, in _call_with_frames_removed
  File "/opt/airflow/dags/weather_data_dag.py", line 8, in <module>
    WORK_DIR = os.environ["WORK_DIR"]
  File "/usr/local/lib/python3.7/os.py", line 681, in __getitem__
    raise KeyError(key) from None
KeyError: 'WORK_DIR'
[2023-08-11T07:59:43.596+0000] {processor.py:838} WARNING - No viable dags retrieved from /opt/airflow/dags/weather_data_dag.py
[2023-08-11T07:59:43.617+0000] {processor.py:179} INFO - Processing /opt/airflow/dags/weather_data_dag.py took 0.036 seconds
[2023-08-11T07:59:47.652+0000] {processor.py:157} INFO - Started process (PID=948) to work on /opt/airflow/dags/weather_data_dag.py
[2023-08-11T07:59:47.652+0000] {processor.py:826} INFO - Processing file /opt/airflow/dags/weather_data_dag.py for tasks to queue
[2023-08-11T07:59:47.653+0000] {logging_mixin.py:150} INFO - [2023-08-11T07:59:47.653+0000] {dagbag.py:541} INFO - Filling up the DagBag from /opt/airflow/dags/weather_data_dag.py
[2023-08-11T07:59:47.669+0000] {logging_mixin.py:150} INFO - [2023-08-11T07:59:47.667+0000] {dagbag.py:350} ERROR - Failed to import: /opt/airflow/dags/weather_data_dag.py
Traceback (most recent call last):
  File "/home/airflow/.local/lib/python3.7/site-packages/airflow/models/dagbag.py", line 346, in parse
    loader.exec_module(new_module)
  File "<frozen importlib._bootstrap_external>", line 728, in exec_module
  File "<frozen importlib._bootstrap>", line 219, in _call_with_frames_removed
  File "/opt/airflow/dags/weather_data_dag.py", line 8, in <module>
    WORK_DIR = os.environ["WORK_DIR"]
  File "/usr/local/lib/python3.7/os.py", line 681, in __getitem__
    raise KeyError(key) from None
KeyError: 'WORK_DIR'
[2023-08-11T07:59:47.669+0000] {processor.py:838} WARNING - No viable dags retrieved from /opt/airflow/dags/weather_data_dag.py
[2023-08-11T07:59:47.699+0000] {processor.py:179} INFO - Processing /opt/airflow/dags/weather_data_dag.py took 0.051 seconds
[2023-08-11T07:59:48.663+0000] {processor.py:157} INFO - Started process (PID=949) to work on /opt/airflow/dags/weather_data_dag.py
[2023-08-11T07:59:48.664+0000] {processor.py:826} INFO - Processing file /opt/airflow/dags/weather_data_dag.py for tasks to queue
[2023-08-11T07:59:48.666+0000] {logging_mixin.py:150} INFO - [2023-08-11T07:59:48.665+0000] {dagbag.py:541} INFO - Filling up the DagBag from /opt/airflow/dags/weather_data_dag.py
[2023-08-11T07:59:48.679+0000] {logging_mixin.py:150} INFO - [2023-08-11T07:59:48.677+0000] {dagbag.py:350} ERROR - Failed to import: /opt/airflow/dags/weather_data_dag.py
Traceback (most recent call last):
  File "/home/airflow/.local/lib/python3.7/site-packages/airflow/models/dagbag.py", line 346, in parse
    loader.exec_module(new_module)
  File "<frozen importlib._bootstrap_external>", line 728, in exec_module
  File "<frozen importlib._bootstrap>", line 219, in _call_with_frames_removed
  File "/opt/airflow/dags/weather_data_dag.py", line 8, in <module>
    WORK_DIR = os.environ["WORK_DIR"]
  File "/usr/local/lib/python3.7/os.py", line 681, in __getitem__
    raise KeyError(key) from None
KeyError: 'WORK_DIR'
[2023-08-11T07:59:48.680+0000] {processor.py:838} WARNING - No viable dags retrieved from /opt/airflow/dags/weather_data_dag.py
[2023-08-11T07:59:48.710+0000] {processor.py:179} INFO - Processing /opt/airflow/dags/weather_data_dag.py took 0.050 seconds
[2023-08-11T07:59:55.524+0000] {processor.py:157} INFO - Started process (PID=965) to work on /opt/airflow/dags/weather_data_dag.py
[2023-08-11T07:59:55.524+0000] {processor.py:826} INFO - Processing file /opt/airflow/dags/weather_data_dag.py for tasks to queue
[2023-08-11T07:59:55.525+0000] {logging_mixin.py:150} INFO - [2023-08-11T07:59:55.525+0000] {dagbag.py:541} INFO - Filling up the DagBag from /opt/airflow/dags/weather_data_dag.py
[2023-08-11T07:59:55.533+0000] {logging_mixin.py:150} INFO - [2023-08-11T07:59:55.532+0000] {dagbag.py:350} ERROR - Failed to import: /opt/airflow/dags/weather_data_dag.py
Traceback (most recent call last):
  File "/home/airflow/.local/lib/python3.7/site-packages/airflow/models/dagbag.py", line 346, in parse
    loader.exec_module(new_module)
  File "<frozen importlib._bootstrap_external>", line 728, in exec_module
  File "<frozen importlib._bootstrap>", line 219, in _call_with_frames_removed
  File "/opt/airflow/dags/weather_data_dag.py", line 8, in <module>
    WORK_DIR = os.environ["WORK_DIR"]
  File "/usr/local/lib/python3.7/os.py", line 681, in __getitem__
    raise KeyError(key) from None
KeyError: 'WORK_DIR'
[2023-08-11T07:59:55.534+0000] {processor.py:838} WARNING - No viable dags retrieved from /opt/airflow/dags/weather_data_dag.py
[2023-08-11T07:59:55.557+0000] {processor.py:179} INFO - Processing /opt/airflow/dags/weather_data_dag.py took 0.036 seconds
[2023-08-11T08:00:12.083+0000] {processor.py:157} INFO - Started process (PID=1016) to work on /opt/airflow/dags/weather_data_dag.py
[2023-08-11T08:00:12.083+0000] {processor.py:826} INFO - Processing file /opt/airflow/dags/weather_data_dag.py for tasks to queue
[2023-08-11T08:00:12.084+0000] {logging_mixin.py:150} INFO - [2023-08-11T08:00:12.084+0000] {dagbag.py:541} INFO - Filling up the DagBag from /opt/airflow/dags/weather_data_dag.py
[2023-08-11T08:00:12.094+0000] {logging_mixin.py:150} INFO - [2023-08-11T08:00:12.093+0000] {dagbag.py:350} ERROR - Failed to import: /opt/airflow/dags/weather_data_dag.py
Traceback (most recent call last):
  File "/home/airflow/.local/lib/python3.7/site-packages/airflow/models/dagbag.py", line 346, in parse
    loader.exec_module(new_module)
  File "<frozen importlib._bootstrap_external>", line 728, in exec_module
  File "<frozen importlib._bootstrap>", line 219, in _call_with_frames_removed
  File "/opt/airflow/dags/weather_data_dag.py", line 8, in <module>
    WORK_DIR = os.environ["WORK_DIR"]
  File "/usr/local/lib/python3.7/os.py", line 681, in __getitem__
    raise KeyError(key) from None
KeyError: 'WORK_DIR'
[2023-08-11T08:00:12.095+0000] {processor.py:838} WARNING - No viable dags retrieved from /opt/airflow/dags/weather_data_dag.py
[2023-08-11T08:00:12.115+0000] {processor.py:179} INFO - Processing /opt/airflow/dags/weather_data_dag.py took 0.035 seconds
[2023-08-11T08:00:15.101+0000] {processor.py:157} INFO - Started process (PID=1017) to work on /opt/airflow/dags/weather_data_dag.py
[2023-08-11T08:00:15.102+0000] {processor.py:826} INFO - Processing file /opt/airflow/dags/weather_data_dag.py for tasks to queue
[2023-08-11T08:00:15.103+0000] {logging_mixin.py:150} INFO - [2023-08-11T08:00:15.102+0000] {dagbag.py:541} INFO - Filling up the DagBag from /opt/airflow/dags/weather_data_dag.py
[2023-08-11T08:00:15.114+0000] {logging_mixin.py:150} INFO - [2023-08-11T08:00:15.112+0000] {dagbag.py:350} ERROR - Failed to import: /opt/airflow/dags/weather_data_dag.py
Traceback (most recent call last):
  File "/home/airflow/.local/lib/python3.7/site-packages/airflow/models/dagbag.py", line 346, in parse
    loader.exec_module(new_module)
  File "<frozen importlib._bootstrap_external>", line 728, in exec_module
  File "<frozen importlib._bootstrap>", line 219, in _call_with_frames_removed
  File "/opt/airflow/dags/weather_data_dag.py", line 9, in <module>
    from weather import WeatherPipline
ModuleNotFoundError: No module named 'weather'
[2023-08-11T08:00:15.114+0000] {processor.py:838} WARNING - No viable dags retrieved from /opt/airflow/dags/weather_data_dag.py
[2023-08-11T08:00:15.134+0000] {processor.py:179} INFO - Processing /opt/airflow/dags/weather_data_dag.py took 0.036 seconds
[2023-08-11T08:00:16.150+0000] {processor.py:157} INFO - Started process (PID=1018) to work on /opt/airflow/dags/weather_data_dag.py
[2023-08-11T08:00:16.151+0000] {processor.py:826} INFO - Processing file /opt/airflow/dags/weather_data_dag.py for tasks to queue
[2023-08-11T08:00:16.152+0000] {logging_mixin.py:150} INFO - [2023-08-11T08:00:16.151+0000] {dagbag.py:541} INFO - Filling up the DagBag from /opt/airflow/dags/weather_data_dag.py
[2023-08-11T08:00:16.160+0000] {logging_mixin.py:150} INFO - [2023-08-11T08:00:16.158+0000] {dagbag.py:350} ERROR - Failed to import: /opt/airflow/dags/weather_data_dag.py
Traceback (most recent call last):
  File "/home/airflow/.local/lib/python3.7/site-packages/airflow/models/dagbag.py", line 346, in parse
    loader.exec_module(new_module)
  File "<frozen importlib._bootstrap_external>", line 728, in exec_module
  File "<frozen importlib._bootstrap>", line 219, in _call_with_frames_removed
  File "/opt/airflow/dags/weather_data_dag.py", line 9, in <module>
    from weather import WeatherPipline
ModuleNotFoundError: No module named 'weather'
[2023-08-11T08:00:16.161+0000] {processor.py:838} WARNING - No viable dags retrieved from /opt/airflow/dags/weather_data_dag.py
[2023-08-11T08:00:16.179+0000] {processor.py:179} INFO - Processing /opt/airflow/dags/weather_data_dag.py took 0.031 seconds
[2023-08-11T08:00:21.194+0000] {processor.py:157} INFO - Started process (PID=1019) to work on /opt/airflow/dags/weather_data_dag.py
[2023-08-11T08:00:21.195+0000] {processor.py:826} INFO - Processing file /opt/airflow/dags/weather_data_dag.py for tasks to queue
[2023-08-11T08:00:21.196+0000] {logging_mixin.py:150} INFO - [2023-08-11T08:00:21.196+0000] {dagbag.py:541} INFO - Filling up the DagBag from /opt/airflow/dags/weather_data_dag.py
[2023-08-11T08:00:21.204+0000] {logging_mixin.py:150} INFO - [2023-08-11T08:00:21.203+0000] {dagbag.py:350} ERROR - Failed to import: /opt/airflow/dags/weather_data_dag.py
Traceback (most recent call last):
  File "/home/airflow/.local/lib/python3.7/site-packages/airflow/models/dagbag.py", line 346, in parse
    loader.exec_module(new_module)
  File "<frozen importlib._bootstrap_external>", line 728, in exec_module
  File "<frozen importlib._bootstrap>", line 219, in _call_with_frames_removed
  File "/opt/airflow/dags/weather_data_dag.py", line 9, in <module>
    from weather import WeatherPipline
ModuleNotFoundError: No module named 'weather'
[2023-08-11T08:00:21.204+0000] {processor.py:838} WARNING - No viable dags retrieved from /opt/airflow/dags/weather_data_dag.py
[2023-08-11T08:00:21.223+0000] {processor.py:179} INFO - Processing /opt/airflow/dags/weather_data_dag.py took 0.034 seconds
[2023-08-11T08:00:26.062+0000] {processor.py:157} INFO - Started process (PID=1035) to work on /opt/airflow/dags/weather_data_dag.py
[2023-08-11T08:00:26.063+0000] {processor.py:826} INFO - Processing file /opt/airflow/dags/weather_data_dag.py for tasks to queue
[2023-08-11T08:00:26.063+0000] {logging_mixin.py:150} INFO - [2023-08-11T08:00:26.063+0000] {dagbag.py:541} INFO - Filling up the DagBag from /opt/airflow/dags/weather_data_dag.py
[2023-08-11T08:00:26.072+0000] {logging_mixin.py:150} INFO - [2023-08-11T08:00:26.072+0000] {dagbag.py:350} ERROR - Failed to import: /opt/airflow/dags/weather_data_dag.py
Traceback (most recent call last):
  File "/home/airflow/.local/lib/python3.7/site-packages/airflow/models/dagbag.py", line 346, in parse
    loader.exec_module(new_module)
  File "<frozen importlib._bootstrap_external>", line 728, in exec_module
  File "<frozen importlib._bootstrap>", line 219, in _call_with_frames_removed
  File "/opt/airflow/dags/weather_data_dag.py", line 9, in <module>
    from weather import WeatherPipline
ModuleNotFoundError: No module named 'weather'
[2023-08-11T08:00:26.073+0000] {processor.py:838} WARNING - No viable dags retrieved from /opt/airflow/dags/weather_data_dag.py
[2023-08-11T08:00:26.096+0000] {processor.py:179} INFO - Processing /opt/airflow/dags/weather_data_dag.py took 0.037 seconds
[2023-08-11T08:00:26.556+0000] {processor.py:157} INFO - Started process (PID=1042) to work on /opt/airflow/dags/weather_data_dag.py
[2023-08-11T08:00:26.557+0000] {processor.py:826} INFO - Processing file /opt/airflow/dags/weather_data_dag.py for tasks to queue
[2023-08-11T08:00:26.558+0000] {logging_mixin.py:150} INFO - [2023-08-11T08:00:26.558+0000] {dagbag.py:541} INFO - Filling up the DagBag from /opt/airflow/dags/weather_data_dag.py
[2023-08-11T08:00:26.567+0000] {logging_mixin.py:150} INFO - [2023-08-11T08:00:26.566+0000] {dagbag.py:350} ERROR - Failed to import: /opt/airflow/dags/weather_data_dag.py
Traceback (most recent call last):
  File "/home/airflow/.local/lib/python3.7/site-packages/airflow/models/dagbag.py", line 346, in parse
    loader.exec_module(new_module)
  File "<frozen importlib._bootstrap_external>", line 728, in exec_module
  File "<frozen importlib._bootstrap>", line 219, in _call_with_frames_removed
  File "/opt/airflow/dags/weather_data_dag.py", line 9, in <module>
    from weather import WeatherPipline
ModuleNotFoundError: No module named 'weather'
[2023-08-11T08:00:26.567+0000] {processor.py:838} WARNING - No viable dags retrieved from /opt/airflow/dags/weather_data_dag.py
[2023-08-11T08:00:26.592+0000] {processor.py:179} INFO - Processing /opt/airflow/dags/weather_data_dag.py took 0.039 seconds
[2023-08-11T08:00:56.685+0000] {processor.py:157} INFO - Started process (PID=1102) to work on /opt/airflow/dags/weather_data_dag.py
[2023-08-11T08:00:56.686+0000] {processor.py:826} INFO - Processing file /opt/airflow/dags/weather_data_dag.py for tasks to queue
[2023-08-11T08:00:56.687+0000] {logging_mixin.py:150} INFO - [2023-08-11T08:00:56.687+0000] {dagbag.py:541} INFO - Filling up the DagBag from /opt/airflow/dags/weather_data_dag.py
[2023-08-11T08:00:56.698+0000] {logging_mixin.py:150} INFO - [2023-08-11T08:00:56.697+0000] {dagbag.py:350} ERROR - Failed to import: /opt/airflow/dags/weather_data_dag.py
Traceback (most recent call last):
  File "/home/airflow/.local/lib/python3.7/site-packages/airflow/models/dagbag.py", line 346, in parse
    loader.exec_module(new_module)
  File "<frozen importlib._bootstrap_external>", line 728, in exec_module
  File "<frozen importlib._bootstrap>", line 219, in _call_with_frames_removed
  File "/opt/airflow/dags/weather_data_dag.py", line 9, in <module>
    from weather import WeatherPipline
ModuleNotFoundError: No module named 'weather'
[2023-08-11T08:00:56.698+0000] {processor.py:838} WARNING - No viable dags retrieved from /opt/airflow/dags/weather_data_dag.py
[2023-08-11T08:00:56.722+0000] {processor.py:179} INFO - Processing /opt/airflow/dags/weather_data_dag.py took 0.039 seconds
[2023-08-11T08:01:06.249+0000] {processor.py:157} INFO - Started process (PID=1140) to work on /opt/airflow/dags/weather_data_dag.py
[2023-08-11T08:01:06.250+0000] {processor.py:826} INFO - Processing file /opt/airflow/dags/weather_data_dag.py for tasks to queue
[2023-08-11T08:01:06.251+0000] {logging_mixin.py:150} INFO - [2023-08-11T08:01:06.251+0000] {dagbag.py:541} INFO - Filling up the DagBag from /opt/airflow/dags/weather_data_dag.py
[2023-08-11T08:01:06.260+0000] {logging_mixin.py:150} INFO - [2023-08-11T08:01:06.259+0000] {dagbag.py:350} ERROR - Failed to import: /opt/airflow/dags/weather_data_dag.py
Traceback (most recent call last):
  File "/home/airflow/.local/lib/python3.7/site-packages/airflow/models/dagbag.py", line 346, in parse
    loader.exec_module(new_module)
  File "<frozen importlib._bootstrap_external>", line 728, in exec_module
  File "<frozen importlib._bootstrap>", line 219, in _call_with_frames_removed
  File "/opt/airflow/dags/weather_data_dag.py", line 9, in <module>
    from .weather import WeatherPipline
ImportError: attempted relative import with no known parent package
[2023-08-11T08:01:06.261+0000] {processor.py:838} WARNING - No viable dags retrieved from /opt/airflow/dags/weather_data_dag.py
[2023-08-11T08:01:06.284+0000] {processor.py:179} INFO - Processing /opt/airflow/dags/weather_data_dag.py took 0.038 seconds
[2023-08-11T08:01:17.257+0000] {processor.py:157} INFO - Started process (PID=1154) to work on /opt/airflow/dags/weather_data_dag.py
[2023-08-11T08:01:17.258+0000] {processor.py:826} INFO - Processing file /opt/airflow/dags/weather_data_dag.py for tasks to queue
[2023-08-11T08:01:17.258+0000] {logging_mixin.py:150} INFO - [2023-08-11T08:01:17.258+0000] {dagbag.py:541} INFO - Filling up the DagBag from /opt/airflow/dags/weather_data_dag.py
[2023-08-11T08:01:17.261+0000] {logging_mixin.py:150} INFO - [2023-08-11T08:01:17.260+0000] {dagbag.py:350} ERROR - Failed to import: /opt/airflow/dags/weather_data_dag.py
Traceback (most recent call last):
  File "/home/airflow/.local/lib/python3.7/site-packages/airflow/models/dagbag.py", line 346, in parse
    loader.exec_module(new_module)
  File "<frozen importlib._bootstrap_external>", line 724, in exec_module
  File "<frozen importlib._bootstrap_external>", line 860, in get_code
  File "<frozen importlib._bootstrap_external>", line 791, in source_to_code
  File "<frozen importlib._bootstrap>", line 219, in _call_with_frames_removed
  File "/opt/airflow/dags/weather_data_dag.py", line 9
    from ../weather import WeatherPipline
           ^
SyntaxError: invalid syntax
[2023-08-11T08:01:17.261+0000] {processor.py:838} WARNING - No viable dags retrieved from /opt/airflow/dags/weather_data_dag.py
[2023-08-11T08:01:17.282+0000] {processor.py:179} INFO - Processing /opt/airflow/dags/weather_data_dag.py took 0.027 seconds
[2023-08-11T08:01:19.275+0000] {processor.py:157} INFO - Started process (PID=1155) to work on /opt/airflow/dags/weather_data_dag.py
[2023-08-11T08:01:19.276+0000] {processor.py:826} INFO - Processing file /opt/airflow/dags/weather_data_dag.py for tasks to queue
[2023-08-11T08:01:19.277+0000] {logging_mixin.py:150} INFO - [2023-08-11T08:01:19.276+0000] {dagbag.py:541} INFO - Filling up the DagBag from /opt/airflow/dags/weather_data_dag.py
[2023-08-11T08:01:19.280+0000] {logging_mixin.py:150} INFO - [2023-08-11T08:01:19.279+0000] {dagbag.py:350} ERROR - Failed to import: /opt/airflow/dags/weather_data_dag.py
Traceback (most recent call last):
  File "/home/airflow/.local/lib/python3.7/site-packages/airflow/models/dagbag.py", line 346, in parse
    loader.exec_module(new_module)
  File "<frozen importlib._bootstrap_external>", line 724, in exec_module
  File "<frozen importlib._bootstrap_external>", line 860, in get_code
  File "<frozen importlib._bootstrap_external>", line 791, in source_to_code
  File "<frozen importlib._bootstrap>", line 219, in _call_with_frames_removed
  File "/opt/airflow/dags/weather_data_dag.py", line 9
    from ./weather import WeatherPipline
          ^
SyntaxError: invalid syntax
[2023-08-11T08:01:19.280+0000] {processor.py:838} WARNING - No viable dags retrieved from /opt/airflow/dags/weather_data_dag.py
[2023-08-11T08:01:19.303+0000] {processor.py:179} INFO - Processing /opt/airflow/dags/weather_data_dag.py took 0.030 seconds
[2023-08-11T08:01:49.477+0000] {processor.py:157} INFO - Started process (PID=1221) to work on /opt/airflow/dags/weather_data_dag.py
[2023-08-11T08:01:49.479+0000] {processor.py:826} INFO - Processing file /opt/airflow/dags/weather_data_dag.py for tasks to queue
[2023-08-11T08:01:49.481+0000] {logging_mixin.py:150} INFO - [2023-08-11T08:01:49.480+0000] {dagbag.py:541} INFO - Filling up the DagBag from /opt/airflow/dags/weather_data_dag.py
[2023-08-11T08:01:49.483+0000] {logging_mixin.py:150} INFO - [2023-08-11T08:01:49.482+0000] {dagbag.py:350} ERROR - Failed to import: /opt/airflow/dags/weather_data_dag.py
Traceback (most recent call last):
  File "/home/airflow/.local/lib/python3.7/site-packages/airflow/models/dagbag.py", line 346, in parse
    loader.exec_module(new_module)
  File "<frozen importlib._bootstrap_external>", line 724, in exec_module
  File "<frozen importlib._bootstrap_external>", line 860, in get_code
  File "<frozen importlib._bootstrap_external>", line 791, in source_to_code
  File "<frozen importlib._bootstrap>", line 219, in _call_with_frames_removed
  File "/opt/airflow/dags/weather_data_dag.py", line 9
    from ./weather import WeatherPipline
          ^
SyntaxError: invalid syntax
[2023-08-11T08:01:49.483+0000] {processor.py:838} WARNING - No viable dags retrieved from /opt/airflow/dags/weather_data_dag.py
[2023-08-11T08:01:49.504+0000] {processor.py:179} INFO - Processing /opt/airflow/dags/weather_data_dag.py took 0.030 seconds
[2023-08-11T08:02:00.840+0000] {processor.py:157} INFO - Started process (PID=1255) to work on /opt/airflow/dags/weather_data_dag.py
[2023-08-11T08:02:00.842+0000] {processor.py:826} INFO - Processing file /opt/airflow/dags/weather_data_dag.py for tasks to queue
[2023-08-11T08:02:00.843+0000] {logging_mixin.py:150} INFO - [2023-08-11T08:02:00.842+0000] {dagbag.py:541} INFO - Filling up the DagBag from /opt/airflow/dags/weather_data_dag.py
[2023-08-11T08:02:00.850+0000] {logging_mixin.py:150} INFO - [2023-08-11T08:02:00.850+0000] {dagbag.py:350} ERROR - Failed to import: /opt/airflow/dags/weather_data_dag.py
Traceback (most recent call last):
  File "/home/airflow/.local/lib/python3.7/site-packages/airflow/models/dagbag.py", line 346, in parse
    loader.exec_module(new_module)
  File "<frozen importlib._bootstrap_external>", line 728, in exec_module
  File "<frozen importlib._bootstrap>", line 219, in _call_with_frames_removed
  File "/opt/airflow/dags/weather_data_dag.py", line 9, in <module>
    from weather import WeatherPipline
ModuleNotFoundError: No module named 'weather'
[2023-08-11T08:02:00.851+0000] {processor.py:838} WARNING - No viable dags retrieved from /opt/airflow/dags/weather_data_dag.py
[2023-08-11T08:02:00.873+0000] {processor.py:179} INFO - Processing /opt/airflow/dags/weather_data_dag.py took 0.036 seconds
[2023-08-11T08:02:00.953+0000] {processor.py:157} INFO - Started process (PID=1257) to work on /opt/airflow/dags/weather_data_dag.py
[2023-08-11T08:02:00.954+0000] {processor.py:826} INFO - Processing file /opt/airflow/dags/weather_data_dag.py for tasks to queue
[2023-08-11T08:02:00.955+0000] {logging_mixin.py:150} INFO - [2023-08-11T08:02:00.955+0000] {dagbag.py:541} INFO - Filling up the DagBag from /opt/airflow/dags/weather_data_dag.py
[2023-08-11T08:02:00.964+0000] {logging_mixin.py:150} INFO - [2023-08-11T08:02:00.963+0000] {dagbag.py:350} ERROR - Failed to import: /opt/airflow/dags/weather_data_dag.py
Traceback (most recent call last):
  File "/home/airflow/.local/lib/python3.7/site-packages/airflow/models/dagbag.py", line 346, in parse
    loader.exec_module(new_module)
  File "<frozen importlib._bootstrap_external>", line 728, in exec_module
  File "<frozen importlib._bootstrap>", line 219, in _call_with_frames_removed
  File "/opt/airflow/dags/weather_data_dag.py", line 9, in <module>
    from weather import WeatherPipline
ModuleNotFoundError: No module named 'weather'
[2023-08-11T08:02:00.964+0000] {processor.py:838} WARNING - No viable dags retrieved from /opt/airflow/dags/weather_data_dag.py
[2023-08-11T08:02:00.983+0000] {processor.py:179} INFO - Processing /opt/airflow/dags/weather_data_dag.py took 0.033 seconds
[2023-08-11T08:02:01.963+0000] {processor.py:157} INFO - Started process (PID=1266) to work on /opt/airflow/dags/weather_data_dag.py
[2023-08-11T08:02:01.964+0000] {processor.py:826} INFO - Processing file /opt/airflow/dags/weather_data_dag.py for tasks to queue
[2023-08-11T08:02:01.967+0000] {logging_mixin.py:150} INFO - [2023-08-11T08:02:01.966+0000] {dagbag.py:541} INFO - Filling up the DagBag from /opt/airflow/dags/weather_data_dag.py
[2023-08-11T08:02:01.977+0000] {logging_mixin.py:150} INFO - [2023-08-11T08:02:01.977+0000] {dagbag.py:350} ERROR - Failed to import: /opt/airflow/dags/weather_data_dag.py
Traceback (most recent call last):
  File "/home/airflow/.local/lib/python3.7/site-packages/airflow/models/dagbag.py", line 346, in parse
    loader.exec_module(new_module)
  File "<frozen importlib._bootstrap_external>", line 728, in exec_module
  File "<frozen importlib._bootstrap>", line 219, in _call_with_frames_removed
  File "/opt/airflow/dags/weather_data_dag.py", line 9, in <module>
    from weather import WeatherPipline
ModuleNotFoundError: No module named 'weather'
[2023-08-11T08:02:01.978+0000] {processor.py:838} WARNING - No viable dags retrieved from /opt/airflow/dags/weather_data_dag.py
[2023-08-11T08:02:02.000+0000] {processor.py:179} INFO - Processing /opt/airflow/dags/weather_data_dag.py took 0.040 seconds
[2023-08-11T08:02:32.120+0000] {processor.py:157} INFO - Started process (PID=1332) to work on /opt/airflow/dags/weather_data_dag.py
[2023-08-11T08:02:32.123+0000] {processor.py:826} INFO - Processing file /opt/airflow/dags/weather_data_dag.py for tasks to queue
[2023-08-11T08:02:32.124+0000] {logging_mixin.py:150} INFO - [2023-08-11T08:02:32.123+0000] {dagbag.py:541} INFO - Filling up the DagBag from /opt/airflow/dags/weather_data_dag.py
[2023-08-11T08:02:32.133+0000] {logging_mixin.py:150} INFO - [2023-08-11T08:02:32.132+0000] {dagbag.py:350} ERROR - Failed to import: /opt/airflow/dags/weather_data_dag.py
Traceback (most recent call last):
  File "/home/airflow/.local/lib/python3.7/site-packages/airflow/models/dagbag.py", line 346, in parse
    loader.exec_module(new_module)
  File "<frozen importlib._bootstrap_external>", line 728, in exec_module
  File "<frozen importlib._bootstrap>", line 219, in _call_with_frames_removed
  File "/opt/airflow/dags/weather_data_dag.py", line 9, in <module>
    from weather import WeatherPipline
ModuleNotFoundError: No module named 'weather'
[2023-08-11T08:02:32.133+0000] {processor.py:838} WARNING - No viable dags retrieved from /opt/airflow/dags/weather_data_dag.py
[2023-08-11T08:02:32.155+0000] {processor.py:179} INFO - Processing /opt/airflow/dags/weather_data_dag.py took 0.038 seconds
[2023-08-11T08:03:02.785+0000] {processor.py:157} INFO - Started process (PID=1398) to work on /opt/airflow/dags/weather_data_dag.py
[2023-08-11T08:03:02.786+0000] {processor.py:826} INFO - Processing file /opt/airflow/dags/weather_data_dag.py for tasks to queue
[2023-08-11T08:03:02.787+0000] {logging_mixin.py:150} INFO - [2023-08-11T08:03:02.786+0000] {dagbag.py:541} INFO - Filling up the DagBag from /opt/airflow/dags/weather_data_dag.py
[2023-08-11T08:03:02.795+0000] {logging_mixin.py:150} INFO - [2023-08-11T08:03:02.795+0000] {dagbag.py:350} ERROR - Failed to import: /opt/airflow/dags/weather_data_dag.py
Traceback (most recent call last):
  File "/home/airflow/.local/lib/python3.7/site-packages/airflow/models/dagbag.py", line 346, in parse
    loader.exec_module(new_module)
  File "<frozen importlib._bootstrap_external>", line 728, in exec_module
  File "<frozen importlib._bootstrap>", line 219, in _call_with_frames_removed
  File "/opt/airflow/dags/weather_data_dag.py", line 9, in <module>
    from weather import WeatherPipline
ModuleNotFoundError: No module named 'weather'
[2023-08-11T08:03:02.796+0000] {processor.py:838} WARNING - No viable dags retrieved from /opt/airflow/dags/weather_data_dag.py
[2023-08-11T08:03:02.816+0000] {processor.py:179} INFO - Processing /opt/airflow/dags/weather_data_dag.py took 0.033 seconds
[2023-08-11T08:03:20.900+0000] {processor.py:157} INFO - Started process (PID=1423) to work on /opt/airflow/dags/weather_data_dag.py
[2023-08-11T08:03:20.902+0000] {processor.py:826} INFO - Processing file /opt/airflow/dags/weather_data_dag.py for tasks to queue
[2023-08-11T08:03:20.903+0000] {logging_mixin.py:150} INFO - [2023-08-11T08:03:20.903+0000] {dagbag.py:541} INFO - Filling up the DagBag from /opt/airflow/dags/weather_data_dag.py
[2023-08-11T08:03:20.911+0000] {logging_mixin.py:150} INFO - [2023-08-11T08:03:20.909+0000] {dagbag.py:350} ERROR - Failed to import: /opt/airflow/dags/weather_data_dag.py
Traceback (most recent call last):
  File "/home/airflow/.local/lib/python3.7/site-packages/airflow/models/dagbag.py", line 346, in parse
    loader.exec_module(new_module)
  File "<frozen importlib._bootstrap_external>", line 728, in exec_module
  File "<frozen importlib._bootstrap>", line 219, in _call_with_frames_removed
  File "/opt/airflow/dags/weather_data_dag.py", line 9, in <module>
    from weather.weather_etl import WeatherPipline
ModuleNotFoundError: No module named 'weather'
[2023-08-11T08:03:20.911+0000] {processor.py:838} WARNING - No viable dags retrieved from /opt/airflow/dags/weather_data_dag.py
[2023-08-11T08:03:20.931+0000] {processor.py:179} INFO - Processing /opt/airflow/dags/weather_data_dag.py took 0.034 seconds
[2023-08-11T08:03:51.309+0000] {processor.py:157} INFO - Started process (PID=1489) to work on /opt/airflow/dags/weather_data_dag.py
[2023-08-11T08:03:51.310+0000] {processor.py:826} INFO - Processing file /opt/airflow/dags/weather_data_dag.py for tasks to queue
[2023-08-11T08:03:51.311+0000] {logging_mixin.py:150} INFO - [2023-08-11T08:03:51.310+0000] {dagbag.py:541} INFO - Filling up the DagBag from /opt/airflow/dags/weather_data_dag.py
[2023-08-11T08:03:51.318+0000] {logging_mixin.py:150} INFO - [2023-08-11T08:03:51.317+0000] {dagbag.py:350} ERROR - Failed to import: /opt/airflow/dags/weather_data_dag.py
Traceback (most recent call last):
  File "/home/airflow/.local/lib/python3.7/site-packages/airflow/models/dagbag.py", line 346, in parse
    loader.exec_module(new_module)
  File "<frozen importlib._bootstrap_external>", line 728, in exec_module
  File "<frozen importlib._bootstrap>", line 219, in _call_with_frames_removed
  File "/opt/airflow/dags/weather_data_dag.py", line 9, in <module>
    from weather.weather_etl import WeatherPipline
ModuleNotFoundError: No module named 'weather'
[2023-08-11T08:03:51.318+0000] {processor.py:838} WARNING - No viable dags retrieved from /opt/airflow/dags/weather_data_dag.py
[2023-08-11T08:03:51.340+0000] {processor.py:179} INFO - Processing /opt/airflow/dags/weather_data_dag.py took 0.033 seconds
[2023-08-11T08:04:21.775+0000] {processor.py:157} INFO - Started process (PID=1563) to work on /opt/airflow/dags/weather_data_dag.py
[2023-08-11T08:04:21.777+0000] {processor.py:826} INFO - Processing file /opt/airflow/dags/weather_data_dag.py for tasks to queue
[2023-08-11T08:04:21.777+0000] {logging_mixin.py:150} INFO - [2023-08-11T08:04:21.777+0000] {dagbag.py:541} INFO - Filling up the DagBag from /opt/airflow/dags/weather_data_dag.py
[2023-08-11T08:04:21.783+0000] {logging_mixin.py:150} INFO - [2023-08-11T08:04:21.783+0000] {dagbag.py:350} ERROR - Failed to import: /opt/airflow/dags/weather_data_dag.py
Traceback (most recent call last):
  File "/home/airflow/.local/lib/python3.7/site-packages/airflow/models/dagbag.py", line 346, in parse
    loader.exec_module(new_module)
  File "<frozen importlib._bootstrap_external>", line 728, in exec_module
  File "<frozen importlib._bootstrap>", line 219, in _call_with_frames_removed
  File "/opt/airflow/dags/weather_data_dag.py", line 9, in <module>
    from weather.weather_etl import WeatherPipline
ModuleNotFoundError: No module named 'weather'
[2023-08-11T08:04:21.784+0000] {processor.py:838} WARNING - No viable dags retrieved from /opt/airflow/dags/weather_data_dag.py
[2023-08-11T08:04:21.804+0000] {processor.py:179} INFO - Processing /opt/airflow/dags/weather_data_dag.py took 0.032 seconds
[2023-08-11T08:04:52.351+0000] {processor.py:157} INFO - Started process (PID=1629) to work on /opt/airflow/dags/weather_data_dag.py
[2023-08-11T08:04:52.352+0000] {processor.py:826} INFO - Processing file /opt/airflow/dags/weather_data_dag.py for tasks to queue
[2023-08-11T08:04:52.353+0000] {logging_mixin.py:150} INFO - [2023-08-11T08:04:52.353+0000] {dagbag.py:541} INFO - Filling up the DagBag from /opt/airflow/dags/weather_data_dag.py
[2023-08-11T08:04:52.360+0000] {logging_mixin.py:150} INFO - [2023-08-11T08:04:52.360+0000] {dagbag.py:350} ERROR - Failed to import: /opt/airflow/dags/weather_data_dag.py
Traceback (most recent call last):
  File "/home/airflow/.local/lib/python3.7/site-packages/airflow/models/dagbag.py", line 346, in parse
    loader.exec_module(new_module)
  File "<frozen importlib._bootstrap_external>", line 728, in exec_module
  File "<frozen importlib._bootstrap>", line 219, in _call_with_frames_removed
  File "/opt/airflow/dags/weather_data_dag.py", line 9, in <module>
    from weather.weather_etl import WeatherPipline
ModuleNotFoundError: No module named 'weather'
[2023-08-11T08:04:52.361+0000] {processor.py:838} WARNING - No viable dags retrieved from /opt/airflow/dags/weather_data_dag.py
[2023-08-11T08:04:52.380+0000] {processor.py:179} INFO - Processing /opt/airflow/dags/weather_data_dag.py took 0.032 seconds
[2023-08-11T08:05:21.489+0000] {processor.py:157} INFO - Started process (PID=1695) to work on /opt/airflow/dags/weather_data_dag.py
[2023-08-11T08:05:21.490+0000] {processor.py:826} INFO - Processing file /opt/airflow/dags/weather_data_dag.py for tasks to queue
[2023-08-11T08:05:21.491+0000] {logging_mixin.py:150} INFO - [2023-08-11T08:05:21.490+0000] {dagbag.py:541} INFO - Filling up the DagBag from /opt/airflow/dags/weather_data_dag.py
[2023-08-11T08:05:21.500+0000] {logging_mixin.py:150} INFO - [2023-08-11T08:05:21.499+0000] {dagbag.py:350} ERROR - Failed to import: /opt/airflow/dags/weather_data_dag.py
Traceback (most recent call last):
  File "/home/airflow/.local/lib/python3.7/site-packages/airflow/models/dagbag.py", line 346, in parse
    loader.exec_module(new_module)
  File "<frozen importlib._bootstrap_external>", line 728, in exec_module
  File "<frozen importlib._bootstrap>", line 219, in _call_with_frames_removed
  File "/opt/airflow/dags/weather_data_dag.py", line 9, in <module>
    from weather.weather_etl import WeatherPipline
ModuleNotFoundError: No module named 'weather'
[2023-08-11T08:05:21.501+0000] {processor.py:838} WARNING - No viable dags retrieved from /opt/airflow/dags/weather_data_dag.py
[2023-08-11T08:05:21.521+0000] {processor.py:179} INFO - Processing /opt/airflow/dags/weather_data_dag.py took 0.035 seconds
[2023-08-11T08:05:22.499+0000] {processor.py:157} INFO - Started process (PID=1696) to work on /opt/airflow/dags/weather_data_dag.py
[2023-08-11T08:05:22.500+0000] {processor.py:826} INFO - Processing file /opt/airflow/dags/weather_data_dag.py for tasks to queue
[2023-08-11T08:05:22.501+0000] {logging_mixin.py:150} INFO - [2023-08-11T08:05:22.500+0000] {dagbag.py:541} INFO - Filling up the DagBag from /opt/airflow/dags/weather_data_dag.py
[2023-08-11T08:05:22.510+0000] {logging_mixin.py:150} INFO - [2023-08-11T08:05:22.509+0000] {dagbag.py:350} ERROR - Failed to import: /opt/airflow/dags/weather_data_dag.py
Traceback (most recent call last):
  File "/home/airflow/.local/lib/python3.7/site-packages/airflow/models/dagbag.py", line 346, in parse
    loader.exec_module(new_module)
  File "<frozen importlib._bootstrap_external>", line 728, in exec_module
  File "<frozen importlib._bootstrap>", line 219, in _call_with_frames_removed
  File "/opt/airflow/dags/weather_data_dag.py", line 9, in <module>
    from weather.weather_etl import WeatherPipline
ModuleNotFoundError: No module named 'weather'
[2023-08-11T08:05:22.510+0000] {processor.py:838} WARNING - No viable dags retrieved from /opt/airflow/dags/weather_data_dag.py
[2023-08-11T08:05:22.530+0000] {processor.py:179} INFO - Processing /opt/airflow/dags/weather_data_dag.py took 0.033 seconds
[2023-08-11T08:05:52.917+0000] {processor.py:157} INFO - Started process (PID=1762) to work on /opt/airflow/dags/weather_data_dag.py
[2023-08-11T08:05:52.929+0000] {processor.py:826} INFO - Processing file /opt/airflow/dags/weather_data_dag.py for tasks to queue
[2023-08-11T08:05:52.931+0000] {logging_mixin.py:150} INFO - [2023-08-11T08:05:52.931+0000] {dagbag.py:541} INFO - Filling up the DagBag from /opt/airflow/dags/weather_data_dag.py
[2023-08-11T08:05:52.947+0000] {logging_mixin.py:150} INFO - [2023-08-11T08:05:52.945+0000] {dagbag.py:350} ERROR - Failed to import: /opt/airflow/dags/weather_data_dag.py
Traceback (most recent call last):
  File "/home/airflow/.local/lib/python3.7/site-packages/airflow/models/dagbag.py", line 346, in parse
    loader.exec_module(new_module)
  File "<frozen importlib._bootstrap_external>", line 728, in exec_module
  File "<frozen importlib._bootstrap>", line 219, in _call_with_frames_removed
  File "/opt/airflow/dags/weather_data_dag.py", line 9, in <module>
    from weather.weather_etl import WeatherPipline
ModuleNotFoundError: No module named 'weather'
[2023-08-11T08:05:52.947+0000] {processor.py:838} WARNING - No viable dags retrieved from /opt/airflow/dags/weather_data_dag.py
[2023-08-11T08:05:52.984+0000] {processor.py:179} INFO - Processing /opt/airflow/dags/weather_data_dag.py took 0.072 seconds
[2023-08-11T08:06:03.624+0000] {processor.py:157} INFO - Started process (PID=1791) to work on /opt/airflow/dags/weather_data_dag.py
[2023-08-11T08:06:03.626+0000] {processor.py:826} INFO - Processing file /opt/airflow/dags/weather_data_dag.py for tasks to queue
[2023-08-11T08:06:03.628+0000] {logging_mixin.py:150} INFO - [2023-08-11T08:06:03.627+0000] {dagbag.py:541} INFO - Filling up the DagBag from /opt/airflow/dags/weather_data_dag.py
[2023-08-11T08:06:03.651+0000] {logging_mixin.py:150} INFO - [2023-08-11T08:06:03.649+0000] {dagbag.py:350} ERROR - Failed to import: /opt/airflow/dags/weather_data_dag.py
Traceback (most recent call last):
  File "/home/airflow/.local/lib/python3.7/site-packages/airflow/models/dagbag.py", line 346, in parse
    loader.exec_module(new_module)
  File "<frozen importlib._bootstrap_external>", line 728, in exec_module
  File "<frozen importlib._bootstrap>", line 219, in _call_with_frames_removed
  File "/opt/airflow/dags/weather_data_dag.py", line 9, in <module>
    from weather.weather_etl import WeatherPipline
ModuleNotFoundError: No module named 'weather'
[2023-08-11T08:06:03.652+0000] {processor.py:838} WARNING - No viable dags retrieved from /opt/airflow/dags/weather_data_dag.py
[2023-08-11T08:06:03.712+0000] {processor.py:179} INFO - Processing /opt/airflow/dags/weather_data_dag.py took 0.096 seconds
[2023-08-11T08:06:18.941+0000] {processor.py:157} INFO - Started process (PID=1816) to work on /opt/airflow/dags/weather_data_dag.py
[2023-08-11T08:06:18.942+0000] {processor.py:826} INFO - Processing file /opt/airflow/dags/weather_data_dag.py for tasks to queue
[2023-08-11T08:06:18.942+0000] {logging_mixin.py:150} INFO - [2023-08-11T08:06:18.942+0000] {dagbag.py:541} INFO - Filling up the DagBag from /opt/airflow/dags/weather_data_dag.py
[2023-08-11T08:06:18.953+0000] {logging_mixin.py:150} INFO - [2023-08-11T08:06:18.952+0000] {dagbag.py:350} ERROR - Failed to import: /opt/airflow/dags/weather_data_dag.py
Traceback (most recent call last):
  File "/home/airflow/.local/lib/python3.7/site-packages/airflow/models/dagbag.py", line 346, in parse
    loader.exec_module(new_module)
  File "<frozen importlib._bootstrap_external>", line 728, in exec_module
  File "<frozen importlib._bootstrap>", line 219, in _call_with_frames_removed
  File "/opt/airflow/dags/weather_data_dag.py", line 9, in <module>
    from weather.weather_etl import WeatherPipline
ModuleNotFoundError: No module named 'weather'
[2023-08-11T08:06:18.953+0000] {processor.py:838} WARNING - No viable dags retrieved from /opt/airflow/dags/weather_data_dag.py
[2023-08-11T08:06:18.973+0000] {processor.py:179} INFO - Processing /opt/airflow/dags/weather_data_dag.py took 0.035 seconds
[2023-08-11T08:06:19.966+0000] {processor.py:157} INFO - Started process (PID=1817) to work on /opt/airflow/dags/weather_data_dag.py
[2023-08-11T08:06:19.967+0000] {processor.py:826} INFO - Processing file /opt/airflow/dags/weather_data_dag.py for tasks to queue
[2023-08-11T08:06:19.967+0000] {logging_mixin.py:150} INFO - [2023-08-11T08:06:19.967+0000] {dagbag.py:541} INFO - Filling up the DagBag from /opt/airflow/dags/weather_data_dag.py
[2023-08-11T08:06:19.975+0000] {logging_mixin.py:150} INFO - [2023-08-11T08:06:19.974+0000] {dagbag.py:350} ERROR - Failed to import: /opt/airflow/dags/weather_data_dag.py
Traceback (most recent call last):
  File "/home/airflow/.local/lib/python3.7/site-packages/airflow/models/dagbag.py", line 346, in parse
    loader.exec_module(new_module)
  File "<frozen importlib._bootstrap_external>", line 728, in exec_module
  File "<frozen importlib._bootstrap>", line 219, in _call_with_frames_removed
  File "/opt/airflow/dags/weather_data_dag.py", line 9, in <module>
    from weather.weather_etl import WeatherPipline
ModuleNotFoundError: No module named 'weather'
[2023-08-11T08:06:19.975+0000] {processor.py:838} WARNING - No viable dags retrieved from /opt/airflow/dags/weather_data_dag.py
[2023-08-11T08:06:19.993+0000] {processor.py:179} INFO - Processing /opt/airflow/dags/weather_data_dag.py took 0.030 seconds
[2023-08-11T08:06:23.482+0000] {processor.py:157} INFO - Started process (PID=1831) to work on /opt/airflow/dags/weather_data_dag.py
[2023-08-11T08:06:23.482+0000] {processor.py:826} INFO - Processing file /opt/airflow/dags/weather_data_dag.py for tasks to queue
[2023-08-11T08:06:23.483+0000] {logging_mixin.py:150} INFO - [2023-08-11T08:06:23.483+0000] {dagbag.py:541} INFO - Filling up the DagBag from /opt/airflow/dags/weather_data_dag.py
[2023-08-11T08:06:23.491+0000] {logging_mixin.py:150} INFO - [2023-08-11T08:06:23.490+0000] {dagbag.py:350} ERROR - Failed to import: /opt/airflow/dags/weather_data_dag.py
Traceback (most recent call last):
  File "/home/airflow/.local/lib/python3.7/site-packages/airflow/models/dagbag.py", line 346, in parse
    loader.exec_module(new_module)
  File "<frozen importlib._bootstrap_external>", line 728, in exec_module
  File "<frozen importlib._bootstrap>", line 219, in _call_with_frames_removed
  File "/opt/airflow/dags/weather_data_dag.py", line 9, in <module>
    from weather.weather_etl import WeatherPipline
ModuleNotFoundError: No module named 'weather'
[2023-08-11T08:06:23.491+0000] {processor.py:838} WARNING - No viable dags retrieved from /opt/airflow/dags/weather_data_dag.py
[2023-08-11T08:06:23.512+0000] {processor.py:179} INFO - Processing /opt/airflow/dags/weather_data_dag.py took 0.033 seconds
[2023-08-11T08:06:24.491+0000] {processor.py:157} INFO - Started process (PID=1832) to work on /opt/airflow/dags/weather_data_dag.py
[2023-08-11T08:06:24.492+0000] {processor.py:826} INFO - Processing file /opt/airflow/dags/weather_data_dag.py for tasks to queue
[2023-08-11T08:06:24.494+0000] {logging_mixin.py:150} INFO - [2023-08-11T08:06:24.493+0000] {dagbag.py:541} INFO - Filling up the DagBag from /opt/airflow/dags/weather_data_dag.py
[2023-08-11T08:06:24.503+0000] {logging_mixin.py:150} INFO - [2023-08-11T08:06:24.502+0000] {dagbag.py:350} ERROR - Failed to import: /opt/airflow/dags/weather_data_dag.py
Traceback (most recent call last):
  File "/home/airflow/.local/lib/python3.7/site-packages/airflow/models/dagbag.py", line 346, in parse
    loader.exec_module(new_module)
  File "<frozen importlib._bootstrap_external>", line 728, in exec_module
  File "<frozen importlib._bootstrap>", line 219, in _call_with_frames_removed
  File "/opt/airflow/dags/weather_data_dag.py", line 9, in <module>
    from weather.weather_etl import WeatherPipline
ModuleNotFoundError: No module named 'weather'
[2023-08-11T08:06:24.503+0000] {processor.py:838} WARNING - No viable dags retrieved from /opt/airflow/dags/weather_data_dag.py
[2023-08-11T08:06:24.524+0000] {processor.py:179} INFO - Processing /opt/airflow/dags/weather_data_dag.py took 0.037 seconds
[2023-08-11T08:06:25.538+0000] {processor.py:157} INFO - Started process (PID=1833) to work on /opt/airflow/dags/weather_data_dag.py
[2023-08-11T08:06:25.539+0000] {processor.py:826} INFO - Processing file /opt/airflow/dags/weather_data_dag.py for tasks to queue
[2023-08-11T08:06:25.539+0000] {logging_mixin.py:150} INFO - [2023-08-11T08:06:25.539+0000] {dagbag.py:541} INFO - Filling up the DagBag from /opt/airflow/dags/weather_data_dag.py
[2023-08-11T08:06:25.547+0000] {logging_mixin.py:150} INFO - [2023-08-11T08:06:25.546+0000] {dagbag.py:350} ERROR - Failed to import: /opt/airflow/dags/weather_data_dag.py
Traceback (most recent call last):
  File "/home/airflow/.local/lib/python3.7/site-packages/airflow/models/dagbag.py", line 346, in parse
    loader.exec_module(new_module)
  File "<frozen importlib._bootstrap_external>", line 728, in exec_module
  File "<frozen importlib._bootstrap>", line 219, in _call_with_frames_removed
  File "/opt/airflow/dags/weather_data_dag.py", line 9, in <module>
    from weather.weather_etl import WeatherPipline
ModuleNotFoundError: No module named 'weather'
[2023-08-11T08:06:25.547+0000] {processor.py:838} WARNING - No viable dags retrieved from /opt/airflow/dags/weather_data_dag.py
[2023-08-11T08:06:25.567+0000] {processor.py:179} INFO - Processing /opt/airflow/dags/weather_data_dag.py took 0.031 seconds
[2023-08-11T08:06:43.678+0000] {processor.py:157} INFO - Started process (PID=1886) to work on /opt/airflow/dags/weather_data_dag.py
[2023-08-11T08:06:43.679+0000] {processor.py:826} INFO - Processing file /opt/airflow/dags/weather_data_dag.py for tasks to queue
[2023-08-11T08:06:43.680+0000] {logging_mixin.py:150} INFO - [2023-08-11T08:06:43.680+0000] {dagbag.py:541} INFO - Filling up the DagBag from /opt/airflow/dags/weather_data_dag.py
[2023-08-11T08:06:43.695+0000] {logging_mixin.py:150} INFO - [2023-08-11T08:06:43.694+0000] {dagbag.py:350} ERROR - Failed to import: /opt/airflow/dags/weather_data_dag.py
Traceback (most recent call last):
  File "/home/airflow/.local/lib/python3.7/site-packages/airflow/models/dagbag.py", line 346, in parse
    loader.exec_module(new_module)
  File "<frozen importlib._bootstrap_external>", line 728, in exec_module
  File "<frozen importlib._bootstrap>", line 219, in _call_with_frames_removed
  File "/opt/airflow/dags/weather_data_dag.py", line 9, in <module>
    from weather_etl import WeatherPipline
ModuleNotFoundError: No module named 'weather_etl'
[2023-08-11T08:06:43.695+0000] {processor.py:838} WARNING - No viable dags retrieved from /opt/airflow/dags/weather_data_dag.py
[2023-08-11T08:06:43.725+0000] {processor.py:179} INFO - Processing /opt/airflow/dags/weather_data_dag.py took 0.051 seconds
[2023-08-11T08:06:57.922+0000] {processor.py:157} INFO - Started process (PID=1902) to work on /opt/airflow/dags/weather_data_dag.py
[2023-08-11T08:06:57.922+0000] {processor.py:826} INFO - Processing file /opt/airflow/dags/weather_data_dag.py for tasks to queue
[2023-08-11T08:06:57.923+0000] {logging_mixin.py:150} INFO - [2023-08-11T08:06:57.923+0000] {dagbag.py:541} INFO - Filling up the DagBag from /opt/airflow/dags/weather_data_dag.py
[2023-08-11T08:06:57.935+0000] {logging_mixin.py:150} INFO - [2023-08-11T08:06:57.934+0000] {dagbag.py:350} ERROR - Failed to import: /opt/airflow/dags/weather_data_dag.py
Traceback (most recent call last):
  File "/home/airflow/.local/lib/python3.7/site-packages/airflow/models/dagbag.py", line 346, in parse
    loader.exec_module(new_module)
  File "<frozen importlib._bootstrap_external>", line 728, in exec_module
  File "<frozen importlib._bootstrap>", line 219, in _call_with_frames_removed
  File "/opt/airflow/dags/weather_data_dag.py", line 9, in <module>
    from weather_etl import WeatherPipline
ModuleNotFoundError: No module named 'weather_etl'
[2023-08-11T08:06:57.935+0000] {processor.py:838} WARNING - No viable dags retrieved from /opt/airflow/dags/weather_data_dag.py
[2023-08-11T08:06:57.954+0000] {processor.py:179} INFO - Processing /opt/airflow/dags/weather_data_dag.py took 0.036 seconds
[2023-08-11T08:06:58.932+0000] {processor.py:157} INFO - Started process (PID=1903) to work on /opt/airflow/dags/weather_data_dag.py
[2023-08-11T08:06:58.933+0000] {processor.py:826} INFO - Processing file /opt/airflow/dags/weather_data_dag.py for tasks to queue
[2023-08-11T08:06:58.934+0000] {logging_mixin.py:150} INFO - [2023-08-11T08:06:58.933+0000] {dagbag.py:541} INFO - Filling up the DagBag from /opt/airflow/dags/weather_data_dag.py
[2023-08-11T08:06:58.942+0000] {logging_mixin.py:150} INFO - [2023-08-11T08:06:58.940+0000] {dagbag.py:350} ERROR - Failed to import: /opt/airflow/dags/weather_data_dag.py
Traceback (most recent call last):
  File "/home/airflow/.local/lib/python3.7/site-packages/airflow/models/dagbag.py", line 346, in parse
    loader.exec_module(new_module)
  File "<frozen importlib._bootstrap_external>", line 728, in exec_module
  File "<frozen importlib._bootstrap>", line 219, in _call_with_frames_removed
  File "/opt/airflow/dags/weather_data_dag.py", line 9, in <module>
    from weather_etl import WeatherPipline
ModuleNotFoundError: No module named 'weather_etl'
[2023-08-11T08:06:58.942+0000] {processor.py:838} WARNING - No viable dags retrieved from /opt/airflow/dags/weather_data_dag.py
[2023-08-11T08:06:58.965+0000] {processor.py:179} INFO - Processing /opt/airflow/dags/weather_data_dag.py took 0.036 seconds
[2023-08-11T08:07:29.584+0000] {processor.py:157} INFO - Started process (PID=1972) to work on /opt/airflow/dags/weather_data_dag.py
[2023-08-11T08:07:29.585+0000] {processor.py:826} INFO - Processing file /opt/airflow/dags/weather_data_dag.py for tasks to queue
[2023-08-11T08:07:29.586+0000] {logging_mixin.py:150} INFO - [2023-08-11T08:07:29.585+0000] {dagbag.py:541} INFO - Filling up the DagBag from /opt/airflow/dags/weather_data_dag.py
[2023-08-11T08:07:29.595+0000] {logging_mixin.py:150} INFO - [2023-08-11T08:07:29.594+0000] {dagbag.py:350} ERROR - Failed to import: /opt/airflow/dags/weather_data_dag.py
Traceback (most recent call last):
  File "/home/airflow/.local/lib/python3.7/site-packages/airflow/models/dagbag.py", line 346, in parse
    loader.exec_module(new_module)
  File "<frozen importlib._bootstrap_external>", line 728, in exec_module
  File "<frozen importlib._bootstrap>", line 219, in _call_with_frames_removed
  File "/opt/airflow/dags/weather_data_dag.py", line 9, in <module>
    from weather_etl import WeatherPipline
ModuleNotFoundError: No module named 'weather_etl'
[2023-08-11T08:07:29.595+0000] {processor.py:838} WARNING - No viable dags retrieved from /opt/airflow/dags/weather_data_dag.py
[2023-08-11T08:07:29.617+0000] {processor.py:179} INFO - Processing /opt/airflow/dags/weather_data_dag.py took 0.036 seconds
[2023-08-11T08:07:59.717+0000] {processor.py:157} INFO - Started process (PID=2038) to work on /opt/airflow/dags/weather_data_dag.py
[2023-08-11T08:07:59.718+0000] {processor.py:826} INFO - Processing file /opt/airflow/dags/weather_data_dag.py for tasks to queue
[2023-08-11T08:07:59.719+0000] {logging_mixin.py:150} INFO - [2023-08-11T08:07:59.718+0000] {dagbag.py:541} INFO - Filling up the DagBag from /opt/airflow/dags/weather_data_dag.py
[2023-08-11T08:07:59.726+0000] {logging_mixin.py:150} INFO - [2023-08-11T08:07:59.725+0000] {dagbag.py:350} ERROR - Failed to import: /opt/airflow/dags/weather_data_dag.py
Traceback (most recent call last):
  File "/home/airflow/.local/lib/python3.7/site-packages/airflow/models/dagbag.py", line 346, in parse
    loader.exec_module(new_module)
  File "<frozen importlib._bootstrap_external>", line 728, in exec_module
  File "<frozen importlib._bootstrap>", line 219, in _call_with_frames_removed
  File "/opt/airflow/dags/weather_data_dag.py", line 9, in <module>
    from weather_etl import WeatherPipline
ModuleNotFoundError: No module named 'weather_etl'
[2023-08-11T08:07:59.726+0000] {processor.py:838} WARNING - No viable dags retrieved from /opt/airflow/dags/weather_data_dag.py
[2023-08-11T08:07:59.748+0000] {processor.py:179} INFO - Processing /opt/airflow/dags/weather_data_dag.py took 0.034 seconds
[2023-08-11T08:08:30.493+0000] {processor.py:157} INFO - Started process (PID=2104) to work on /opt/airflow/dags/weather_data_dag.py
[2023-08-11T08:08:30.494+0000] {processor.py:826} INFO - Processing file /opt/airflow/dags/weather_data_dag.py for tasks to queue
[2023-08-11T08:08:30.495+0000] {logging_mixin.py:150} INFO - [2023-08-11T08:08:30.495+0000] {dagbag.py:541} INFO - Filling up the DagBag from /opt/airflow/dags/weather_data_dag.py
[2023-08-11T08:08:30.503+0000] {logging_mixin.py:150} INFO - [2023-08-11T08:08:30.502+0000] {dagbag.py:350} ERROR - Failed to import: /opt/airflow/dags/weather_data_dag.py
Traceback (most recent call last):
  File "/home/airflow/.local/lib/python3.7/site-packages/airflow/models/dagbag.py", line 346, in parse
    loader.exec_module(new_module)
  File "<frozen importlib._bootstrap_external>", line 728, in exec_module
  File "<frozen importlib._bootstrap>", line 219, in _call_with_frames_removed
  File "/opt/airflow/dags/weather_data_dag.py", line 9, in <module>
    from weather_etl import WeatherPipline
ModuleNotFoundError: No module named 'weather_etl'
[2023-08-11T08:08:30.503+0000] {processor.py:838} WARNING - No viable dags retrieved from /opt/airflow/dags/weather_data_dag.py
[2023-08-11T08:08:30.524+0000] {processor.py:179} INFO - Processing /opt/airflow/dags/weather_data_dag.py took 0.034 seconds
[2023-08-11T08:09:00.905+0000] {processor.py:157} INFO - Started process (PID=2170) to work on /opt/airflow/dags/weather_data_dag.py
[2023-08-11T08:09:00.911+0000] {processor.py:826} INFO - Processing file /opt/airflow/dags/weather_data_dag.py for tasks to queue
[2023-08-11T08:09:00.912+0000] {logging_mixin.py:150} INFO - [2023-08-11T08:09:00.912+0000] {dagbag.py:541} INFO - Filling up the DagBag from /opt/airflow/dags/weather_data_dag.py
[2023-08-11T08:09:00.920+0000] {logging_mixin.py:150} INFO - [2023-08-11T08:09:00.919+0000] {dagbag.py:350} ERROR - Failed to import: /opt/airflow/dags/weather_data_dag.py
Traceback (most recent call last):
  File "/home/airflow/.local/lib/python3.7/site-packages/airflow/models/dagbag.py", line 346, in parse
    loader.exec_module(new_module)
  File "<frozen importlib._bootstrap_external>", line 728, in exec_module
  File "<frozen importlib._bootstrap>", line 219, in _call_with_frames_removed
  File "/opt/airflow/dags/weather_data_dag.py", line 9, in <module>
    from weather_etl import WeatherPipline
ModuleNotFoundError: No module named 'weather_etl'
[2023-08-11T08:09:00.921+0000] {processor.py:838} WARNING - No viable dags retrieved from /opt/airflow/dags/weather_data_dag.py
[2023-08-11T08:09:00.943+0000] {processor.py:179} INFO - Processing /opt/airflow/dags/weather_data_dag.py took 0.041 seconds
[2023-08-11T08:09:31.730+0000] {processor.py:157} INFO - Started process (PID=2236) to work on /opt/airflow/dags/weather_data_dag.py
[2023-08-11T08:09:31.732+0000] {processor.py:826} INFO - Processing file /opt/airflow/dags/weather_data_dag.py for tasks to queue
[2023-08-11T08:09:31.735+0000] {logging_mixin.py:150} INFO - [2023-08-11T08:09:31.734+0000] {dagbag.py:541} INFO - Filling up the DagBag from /opt/airflow/dags/weather_data_dag.py
[2023-08-11T08:09:31.752+0000] {logging_mixin.py:150} INFO - [2023-08-11T08:09:31.751+0000] {dagbag.py:350} ERROR - Failed to import: /opt/airflow/dags/weather_data_dag.py
Traceback (most recent call last):
  File "/home/airflow/.local/lib/python3.7/site-packages/airflow/models/dagbag.py", line 346, in parse
    loader.exec_module(new_module)
  File "<frozen importlib._bootstrap_external>", line 728, in exec_module
  File "<frozen importlib._bootstrap>", line 219, in _call_with_frames_removed
  File "/opt/airflow/dags/weather_data_dag.py", line 9, in <module>
    from weather_etl import WeatherPipline
ModuleNotFoundError: No module named 'weather_etl'
[2023-08-11T08:09:31.753+0000] {processor.py:838} WARNING - No viable dags retrieved from /opt/airflow/dags/weather_data_dag.py
[2023-08-11T08:09:31.791+0000] {processor.py:179} INFO - Processing /opt/airflow/dags/weather_data_dag.py took 0.068 seconds
[2023-08-11T08:10:02.027+0000] {processor.py:157} INFO - Started process (PID=2302) to work on /opt/airflow/dags/weather_data_dag.py
[2023-08-11T08:10:02.035+0000] {processor.py:826} INFO - Processing file /opt/airflow/dags/weather_data_dag.py for tasks to queue
[2023-08-11T08:10:02.037+0000] {logging_mixin.py:150} INFO - [2023-08-11T08:10:02.036+0000] {dagbag.py:541} INFO - Filling up the DagBag from /opt/airflow/dags/weather_data_dag.py
[2023-08-11T08:10:02.045+0000] {logging_mixin.py:150} INFO - [2023-08-11T08:10:02.044+0000] {dagbag.py:350} ERROR - Failed to import: /opt/airflow/dags/weather_data_dag.py
Traceback (most recent call last):
  File "/home/airflow/.local/lib/python3.7/site-packages/airflow/models/dagbag.py", line 346, in parse
    loader.exec_module(new_module)
  File "<frozen importlib._bootstrap_external>", line 728, in exec_module
  File "<frozen importlib._bootstrap>", line 219, in _call_with_frames_removed
  File "/opt/airflow/dags/weather_data_dag.py", line 9, in <module>
    from weather_etl import WeatherPipline
ModuleNotFoundError: No module named 'weather_etl'
[2023-08-11T08:10:02.045+0000] {processor.py:838} WARNING - No viable dags retrieved from /opt/airflow/dags/weather_data_dag.py
[2023-08-11T08:10:02.069+0000] {processor.py:179} INFO - Processing /opt/airflow/dags/weather_data_dag.py took 0.046 seconds
[2023-08-11T08:10:32.389+0000] {processor.py:157} INFO - Started process (PID=2368) to work on /opt/airflow/dags/weather_data_dag.py
[2023-08-11T08:10:32.390+0000] {processor.py:826} INFO - Processing file /opt/airflow/dags/weather_data_dag.py for tasks to queue
[2023-08-11T08:10:32.391+0000] {logging_mixin.py:150} INFO - [2023-08-11T08:10:32.391+0000] {dagbag.py:541} INFO - Filling up the DagBag from /opt/airflow/dags/weather_data_dag.py
[2023-08-11T08:10:32.401+0000] {logging_mixin.py:150} INFO - [2023-08-11T08:10:32.399+0000] {dagbag.py:350} ERROR - Failed to import: /opt/airflow/dags/weather_data_dag.py
Traceback (most recent call last):
  File "/home/airflow/.local/lib/python3.7/site-packages/airflow/models/dagbag.py", line 346, in parse
    loader.exec_module(new_module)
  File "<frozen importlib._bootstrap_external>", line 728, in exec_module
  File "<frozen importlib._bootstrap>", line 219, in _call_with_frames_removed
  File "/opt/airflow/dags/weather_data_dag.py", line 9, in <module>
    from weather_etl import WeatherPipline
ModuleNotFoundError: No module named 'weather_etl'
[2023-08-11T08:10:32.401+0000] {processor.py:838} WARNING - No viable dags retrieved from /opt/airflow/dags/weather_data_dag.py
[2023-08-11T08:10:32.443+0000] {processor.py:179} INFO - Processing /opt/airflow/dags/weather_data_dag.py took 0.060 seconds
[2023-08-11T08:11:02.792+0000] {processor.py:157} INFO - Started process (PID=2434) to work on /opt/airflow/dags/weather_data_dag.py
[2023-08-11T08:11:02.794+0000] {processor.py:826} INFO - Processing file /opt/airflow/dags/weather_data_dag.py for tasks to queue
[2023-08-11T08:11:02.795+0000] {logging_mixin.py:150} INFO - [2023-08-11T08:11:02.795+0000] {dagbag.py:541} INFO - Filling up the DagBag from /opt/airflow/dags/weather_data_dag.py
[2023-08-11T08:11:02.801+0000] {logging_mixin.py:150} INFO - [2023-08-11T08:11:02.801+0000] {dagbag.py:350} ERROR - Failed to import: /opt/airflow/dags/weather_data_dag.py
Traceback (most recent call last):
  File "/home/airflow/.local/lib/python3.7/site-packages/airflow/models/dagbag.py", line 346, in parse
    loader.exec_module(new_module)
  File "<frozen importlib._bootstrap_external>", line 728, in exec_module
  File "<frozen importlib._bootstrap>", line 219, in _call_with_frames_removed
  File "/opt/airflow/dags/weather_data_dag.py", line 9, in <module>
    from weather_etl import WeatherPipline
ModuleNotFoundError: No module named 'weather_etl'
[2023-08-11T08:11:02.802+0000] {processor.py:838} WARNING - No viable dags retrieved from /opt/airflow/dags/weather_data_dag.py
[2023-08-11T08:11:02.827+0000] {processor.py:179} INFO - Processing /opt/airflow/dags/weather_data_dag.py took 0.038 seconds
[2023-08-11T08:11:33.627+0000] {processor.py:157} INFO - Started process (PID=2508) to work on /opt/airflow/dags/weather_data_dag.py
[2023-08-11T08:11:33.627+0000] {processor.py:826} INFO - Processing file /opt/airflow/dags/weather_data_dag.py for tasks to queue
[2023-08-11T08:11:33.628+0000] {logging_mixin.py:150} INFO - [2023-08-11T08:11:33.628+0000] {dagbag.py:541} INFO - Filling up the DagBag from /opt/airflow/dags/weather_data_dag.py
[2023-08-11T08:11:33.634+0000] {logging_mixin.py:150} INFO - [2023-08-11T08:11:33.634+0000] {dagbag.py:350} ERROR - Failed to import: /opt/airflow/dags/weather_data_dag.py
Traceback (most recent call last):
  File "/home/airflow/.local/lib/python3.7/site-packages/airflow/models/dagbag.py", line 346, in parse
    loader.exec_module(new_module)
  File "<frozen importlib._bootstrap_external>", line 728, in exec_module
  File "<frozen importlib._bootstrap>", line 219, in _call_with_frames_removed
  File "/opt/airflow/dags/weather_data_dag.py", line 9, in <module>
    from weather_etl import WeatherPipline
ModuleNotFoundError: No module named 'weather_etl'
[2023-08-11T08:11:33.635+0000] {processor.py:838} WARNING - No viable dags retrieved from /opt/airflow/dags/weather_data_dag.py
[2023-08-11T08:11:33.661+0000] {processor.py:179} INFO - Processing /opt/airflow/dags/weather_data_dag.py took 0.038 seconds
[2023-08-11T08:12:04.255+0000] {processor.py:157} INFO - Started process (PID=2574) to work on /opt/airflow/dags/weather_data_dag.py
[2023-08-11T08:12:04.257+0000] {processor.py:826} INFO - Processing file /opt/airflow/dags/weather_data_dag.py for tasks to queue
[2023-08-11T08:12:04.259+0000] {logging_mixin.py:150} INFO - [2023-08-11T08:12:04.258+0000] {dagbag.py:541} INFO - Filling up the DagBag from /opt/airflow/dags/weather_data_dag.py
[2023-08-11T08:12:04.266+0000] {logging_mixin.py:150} INFO - [2023-08-11T08:12:04.265+0000] {dagbag.py:350} ERROR - Failed to import: /opt/airflow/dags/weather_data_dag.py
Traceback (most recent call last):
  File "/home/airflow/.local/lib/python3.7/site-packages/airflow/models/dagbag.py", line 346, in parse
    loader.exec_module(new_module)
  File "<frozen importlib._bootstrap_external>", line 728, in exec_module
  File "<frozen importlib._bootstrap>", line 219, in _call_with_frames_removed
  File "/opt/airflow/dags/weather_data_dag.py", line 9, in <module>
    from weather_etl import WeatherPipline
ModuleNotFoundError: No module named 'weather_etl'
[2023-08-11T08:12:04.266+0000] {processor.py:838} WARNING - No viable dags retrieved from /opt/airflow/dags/weather_data_dag.py
[2023-08-11T08:12:04.288+0000] {processor.py:179} INFO - Processing /opt/airflow/dags/weather_data_dag.py took 0.035 seconds
[2023-08-11T08:12:34.433+0000] {processor.py:157} INFO - Started process (PID=2640) to work on /opt/airflow/dags/weather_data_dag.py
[2023-08-11T08:12:34.434+0000] {processor.py:826} INFO - Processing file /opt/airflow/dags/weather_data_dag.py for tasks to queue
[2023-08-11T08:12:34.434+0000] {logging_mixin.py:150} INFO - [2023-08-11T08:12:34.434+0000] {dagbag.py:541} INFO - Filling up the DagBag from /opt/airflow/dags/weather_data_dag.py
[2023-08-11T08:12:34.441+0000] {logging_mixin.py:150} INFO - [2023-08-11T08:12:34.440+0000] {dagbag.py:350} ERROR - Failed to import: /opt/airflow/dags/weather_data_dag.py
Traceback (most recent call last):
  File "/home/airflow/.local/lib/python3.7/site-packages/airflow/models/dagbag.py", line 346, in parse
    loader.exec_module(new_module)
  File "<frozen importlib._bootstrap_external>", line 728, in exec_module
  File "<frozen importlib._bootstrap>", line 219, in _call_with_frames_removed
  File "/opt/airflow/dags/weather_data_dag.py", line 9, in <module>
    from weather_etl import WeatherPipline
ModuleNotFoundError: No module named 'weather_etl'
[2023-08-11T08:12:34.442+0000] {processor.py:838} WARNING - No viable dags retrieved from /opt/airflow/dags/weather_data_dag.py
[2023-08-11T08:12:34.466+0000] {processor.py:179} INFO - Processing /opt/airflow/dags/weather_data_dag.py took 0.036 seconds
[2023-08-11T08:13:05.186+0000] {processor.py:157} INFO - Started process (PID=2706) to work on /opt/airflow/dags/weather_data_dag.py
[2023-08-11T08:13:05.188+0000] {processor.py:826} INFO - Processing file /opt/airflow/dags/weather_data_dag.py for tasks to queue
[2023-08-11T08:13:05.189+0000] {logging_mixin.py:150} INFO - [2023-08-11T08:13:05.189+0000] {dagbag.py:541} INFO - Filling up the DagBag from /opt/airflow/dags/weather_data_dag.py
[2023-08-11T08:13:05.206+0000] {logging_mixin.py:150} INFO - [2023-08-11T08:13:05.205+0000] {dagbag.py:350} ERROR - Failed to import: /opt/airflow/dags/weather_data_dag.py
Traceback (most recent call last):
  File "/home/airflow/.local/lib/python3.7/site-packages/airflow/models/dagbag.py", line 346, in parse
    loader.exec_module(new_module)
  File "<frozen importlib._bootstrap_external>", line 728, in exec_module
  File "<frozen importlib._bootstrap>", line 219, in _call_with_frames_removed
  File "/opt/airflow/dags/weather_data_dag.py", line 9, in <module>
    from weather_etl import WeatherPipline
ModuleNotFoundError: No module named 'weather_etl'
[2023-08-11T08:13:05.207+0000] {processor.py:838} WARNING - No viable dags retrieved from /opt/airflow/dags/weather_data_dag.py
[2023-08-11T08:13:05.249+0000] {processor.py:179} INFO - Processing /opt/airflow/dags/weather_data_dag.py took 0.070 seconds
[2023-08-11T08:13:35.741+0000] {processor.py:157} INFO - Started process (PID=2772) to work on /opt/airflow/dags/weather_data_dag.py
[2023-08-11T08:13:35.742+0000] {processor.py:826} INFO - Processing file /opt/airflow/dags/weather_data_dag.py for tasks to queue
[2023-08-11T08:13:35.743+0000] {logging_mixin.py:150} INFO - [2023-08-11T08:13:35.743+0000] {dagbag.py:541} INFO - Filling up the DagBag from /opt/airflow/dags/weather_data_dag.py
[2023-08-11T08:13:35.754+0000] {logging_mixin.py:150} INFO - [2023-08-11T08:13:35.753+0000] {dagbag.py:350} ERROR - Failed to import: /opt/airflow/dags/weather_data_dag.py
Traceback (most recent call last):
  File "/home/airflow/.local/lib/python3.7/site-packages/airflow/models/dagbag.py", line 346, in parse
    loader.exec_module(new_module)
  File "<frozen importlib._bootstrap_external>", line 728, in exec_module
  File "<frozen importlib._bootstrap>", line 219, in _call_with_frames_removed
  File "/opt/airflow/dags/weather_data_dag.py", line 9, in <module>
    from weather_etl import WeatherPipline
ModuleNotFoundError: No module named 'weather_etl'
[2023-08-11T08:13:35.754+0000] {processor.py:838} WARNING - No viable dags retrieved from /opt/airflow/dags/weather_data_dag.py
[2023-08-11T08:13:35.776+0000] {processor.py:179} INFO - Processing /opt/airflow/dags/weather_data_dag.py took 0.038 seconds
[2023-08-11T08:14:05.884+0000] {processor.py:157} INFO - Started process (PID=2838) to work on /opt/airflow/dags/weather_data_dag.py
[2023-08-11T08:14:05.885+0000] {processor.py:826} INFO - Processing file /opt/airflow/dags/weather_data_dag.py for tasks to queue
[2023-08-11T08:14:05.885+0000] {logging_mixin.py:150} INFO - [2023-08-11T08:14:05.885+0000] {dagbag.py:541} INFO - Filling up the DagBag from /opt/airflow/dags/weather_data_dag.py
[2023-08-11T08:14:05.892+0000] {logging_mixin.py:150} INFO - [2023-08-11T08:14:05.891+0000] {dagbag.py:350} ERROR - Failed to import: /opt/airflow/dags/weather_data_dag.py
Traceback (most recent call last):
  File "/home/airflow/.local/lib/python3.7/site-packages/airflow/models/dagbag.py", line 346, in parse
    loader.exec_module(new_module)
  File "<frozen importlib._bootstrap_external>", line 728, in exec_module
  File "<frozen importlib._bootstrap>", line 219, in _call_with_frames_removed
  File "/opt/airflow/dags/weather_data_dag.py", line 9, in <module>
    from weather_etl import WeatherPipline
ModuleNotFoundError: No module named 'weather_etl'
[2023-08-11T08:14:05.892+0000] {processor.py:838} WARNING - No viable dags retrieved from /opt/airflow/dags/weather_data_dag.py
[2023-08-11T08:14:05.920+0000] {processor.py:179} INFO - Processing /opt/airflow/dags/weather_data_dag.py took 0.038 seconds
[2023-08-11T08:14:36.225+0000] {processor.py:157} INFO - Started process (PID=2905) to work on /opt/airflow/dags/weather_data_dag.py
[2023-08-11T08:14:36.226+0000] {processor.py:826} INFO - Processing file /opt/airflow/dags/weather_data_dag.py for tasks to queue
[2023-08-11T08:14:36.227+0000] {logging_mixin.py:150} INFO - [2023-08-11T08:14:36.227+0000] {dagbag.py:541} INFO - Filling up the DagBag from /opt/airflow/dags/weather_data_dag.py
[2023-08-11T08:14:36.238+0000] {logging_mixin.py:150} INFO - [2023-08-11T08:14:36.237+0000] {dagbag.py:350} ERROR - Failed to import: /opt/airflow/dags/weather_data_dag.py
Traceback (most recent call last):
  File "/home/airflow/.local/lib/python3.7/site-packages/airflow/models/dagbag.py", line 346, in parse
    loader.exec_module(new_module)
  File "<frozen importlib._bootstrap_external>", line 728, in exec_module
  File "<frozen importlib._bootstrap>", line 219, in _call_with_frames_removed
  File "/opt/airflow/dags/weather_data_dag.py", line 9, in <module>
    from weather_etl import WeatherPipline
ModuleNotFoundError: No module named 'weather_etl'
[2023-08-11T08:14:36.238+0000] {processor.py:838} WARNING - No viable dags retrieved from /opt/airflow/dags/weather_data_dag.py
[2023-08-11T08:14:36.265+0000] {processor.py:179} INFO - Processing /opt/airflow/dags/weather_data_dag.py took 0.044 seconds
[2023-08-11T08:15:06.831+0000] {processor.py:157} INFO - Started process (PID=2971) to work on /opt/airflow/dags/weather_data_dag.py
[2023-08-11T08:15:06.832+0000] {processor.py:826} INFO - Processing file /opt/airflow/dags/weather_data_dag.py for tasks to queue
[2023-08-11T08:15:06.833+0000] {logging_mixin.py:150} INFO - [2023-08-11T08:15:06.833+0000] {dagbag.py:541} INFO - Filling up the DagBag from /opt/airflow/dags/weather_data_dag.py
[2023-08-11T08:15:06.840+0000] {logging_mixin.py:150} INFO - [2023-08-11T08:15:06.839+0000] {dagbag.py:350} ERROR - Failed to import: /opt/airflow/dags/weather_data_dag.py
Traceback (most recent call last):
  File "/home/airflow/.local/lib/python3.7/site-packages/airflow/models/dagbag.py", line 346, in parse
    loader.exec_module(new_module)
  File "<frozen importlib._bootstrap_external>", line 728, in exec_module
  File "<frozen importlib._bootstrap>", line 219, in _call_with_frames_removed
  File "/opt/airflow/dags/weather_data_dag.py", line 9, in <module>
    from weather_etl import WeatherPipline
ModuleNotFoundError: No module named 'weather_etl'
[2023-08-11T08:15:06.840+0000] {processor.py:838} WARNING - No viable dags retrieved from /opt/airflow/dags/weather_data_dag.py
[2023-08-11T08:15:06.864+0000] {processor.py:179} INFO - Processing /opt/airflow/dags/weather_data_dag.py took 0.036 seconds
[2023-08-11T08:15:24.429+0000] {processor.py:157} INFO - Started process (PID=3014) to work on /opt/airflow/dags/weather_data_dag.py
[2023-08-11T08:15:24.431+0000] {processor.py:826} INFO - Processing file /opt/airflow/dags/weather_data_dag.py for tasks to queue
[2023-08-11T08:15:24.432+0000] {logging_mixin.py:150} INFO - [2023-08-11T08:15:24.432+0000] {dagbag.py:541} INFO - Filling up the DagBag from /opt/airflow/dags/weather_data_dag.py
[2023-08-11T08:15:24.444+0000] {logging_mixin.py:150} INFO - [2023-08-11T08:15:24.441+0000] {dagbag.py:350} ERROR - Failed to import: /opt/airflow/dags/weather_data_dag.py
Traceback (most recent call last):
  File "/home/airflow/.local/lib/python3.7/site-packages/airflow/models/dagbag.py", line 346, in parse
    loader.exec_module(new_module)
  File "<frozen importlib._bootstrap_external>", line 728, in exec_module
  File "<frozen importlib._bootstrap>", line 219, in _call_with_frames_removed
  File "/opt/airflow/dags/weather_data_dag.py", line 9, in <module>
    from weather_etl import WeatherPipline
ModuleNotFoundError: No module named 'weather_etl'
[2023-08-11T08:15:24.444+0000] {processor.py:838} WARNING - No viable dags retrieved from /opt/airflow/dags/weather_data_dag.py
[2023-08-11T08:15:24.470+0000] {processor.py:179} INFO - Processing /opt/airflow/dags/weather_data_dag.py took 0.045 seconds
[2023-08-11T08:15:24.817+0000] {processor.py:157} INFO - Started process (PID=3016) to work on /opt/airflow/dags/weather_data_dag.py
[2023-08-11T08:15:24.818+0000] {processor.py:826} INFO - Processing file /opt/airflow/dags/weather_data_dag.py for tasks to queue
[2023-08-11T08:15:24.819+0000] {logging_mixin.py:150} INFO - [2023-08-11T08:15:24.818+0000] {dagbag.py:541} INFO - Filling up the DagBag from /opt/airflow/dags/weather_data_dag.py
[2023-08-11T08:15:24.829+0000] {logging_mixin.py:150} INFO - [2023-08-11T08:15:24.829+0000] {dagbag.py:350} ERROR - Failed to import: /opt/airflow/dags/weather_data_dag.py
Traceback (most recent call last):
  File "/home/airflow/.local/lib/python3.7/site-packages/airflow/models/dagbag.py", line 346, in parse
    loader.exec_module(new_module)
  File "<frozen importlib._bootstrap_external>", line 728, in exec_module
  File "<frozen importlib._bootstrap>", line 219, in _call_with_frames_removed
  File "/opt/airflow/dags/weather_data_dag.py", line 9, in <module>
    from weather_etl import WeatherPipline
ModuleNotFoundError: No module named 'weather_etl'
[2023-08-11T08:15:24.830+0000] {processor.py:838} WARNING - No viable dags retrieved from /opt/airflow/dags/weather_data_dag.py
[2023-08-11T08:15:24.852+0000] {processor.py:179} INFO - Processing /opt/airflow/dags/weather_data_dag.py took 0.037 seconds
[2023-08-11T08:15:55.588+0000] {processor.py:157} INFO - Started process (PID=3081) to work on /opt/airflow/dags/weather_data_dag.py
[2023-08-11T08:15:55.590+0000] {processor.py:826} INFO - Processing file /opt/airflow/dags/weather_data_dag.py for tasks to queue
[2023-08-11T08:15:55.591+0000] {logging_mixin.py:150} INFO - [2023-08-11T08:15:55.590+0000] {dagbag.py:541} INFO - Filling up the DagBag from /opt/airflow/dags/weather_data_dag.py
[2023-08-11T08:15:55.601+0000] {logging_mixin.py:150} INFO - [2023-08-11T08:15:55.601+0000] {dagbag.py:350} ERROR - Failed to import: /opt/airflow/dags/weather_data_dag.py
Traceback (most recent call last):
  File "/home/airflow/.local/lib/python3.7/site-packages/airflow/models/dagbag.py", line 346, in parse
    loader.exec_module(new_module)
  File "<frozen importlib._bootstrap_external>", line 728, in exec_module
  File "<frozen importlib._bootstrap>", line 219, in _call_with_frames_removed
  File "/opt/airflow/dags/weather_data_dag.py", line 9, in <module>
    from weather_etl import WeatherPipline
ModuleNotFoundError: No module named 'weather_etl'
[2023-08-11T08:15:55.602+0000] {processor.py:838} WARNING - No viable dags retrieved from /opt/airflow/dags/weather_data_dag.py
[2023-08-11T08:15:55.622+0000] {processor.py:179} INFO - Processing /opt/airflow/dags/weather_data_dag.py took 0.038 seconds
[2023-08-11T08:16:15.644+0000] {processor.py:157} INFO - Started process (PID=3124) to work on /opt/airflow/dags/weather_data_dag.py
[2023-08-11T08:16:15.645+0000] {processor.py:826} INFO - Processing file /opt/airflow/dags/weather_data_dag.py for tasks to queue
[2023-08-11T08:16:15.646+0000] {logging_mixin.py:150} INFO - [2023-08-11T08:16:15.646+0000] {dagbag.py:541} INFO - Filling up the DagBag from /opt/airflow/dags/weather_data_dag.py
[2023-08-11T08:16:15.656+0000] {logging_mixin.py:150} INFO - [2023-08-11T08:16:15.655+0000] {dagbag.py:350} ERROR - Failed to import: /opt/airflow/dags/weather_data_dag.py
Traceback (most recent call last):
  File "/home/airflow/.local/lib/python3.7/site-packages/airflow/models/dagbag.py", line 346, in parse
    loader.exec_module(new_module)
  File "<frozen importlib._bootstrap_external>", line 728, in exec_module
  File "<frozen importlib._bootstrap>", line 219, in _call_with_frames_removed
  File "/opt/airflow/dags/weather_data_dag.py", line 9, in <module>
    from weather_etl import WeatherPipeline
ModuleNotFoundError: No module named 'weather_etl'
[2023-08-11T08:16:15.656+0000] {processor.py:838} WARNING - No viable dags retrieved from /opt/airflow/dags/weather_data_dag.py
[2023-08-11T08:16:15.746+0000] {processor.py:179} INFO - Processing /opt/airflow/dags/weather_data_dag.py took 0.105 seconds
[2023-08-11T08:16:15.948+0000] {processor.py:157} INFO - Started process (PID=3128) to work on /opt/airflow/dags/weather_data_dag.py
[2023-08-11T08:16:15.949+0000] {processor.py:826} INFO - Processing file /opt/airflow/dags/weather_data_dag.py for tasks to queue
[2023-08-11T08:16:15.952+0000] {logging_mixin.py:150} INFO - [2023-08-11T08:16:15.951+0000] {dagbag.py:541} INFO - Filling up the DagBag from /opt/airflow/dags/weather_data_dag.py
[2023-08-11T08:16:15.965+0000] {logging_mixin.py:150} INFO - [2023-08-11T08:16:15.964+0000] {dagbag.py:350} ERROR - Failed to import: /opt/airflow/dags/weather_data_dag.py
Traceback (most recent call last):
  File "/home/airflow/.local/lib/python3.7/site-packages/airflow/models/dagbag.py", line 346, in parse
    loader.exec_module(new_module)
  File "<frozen importlib._bootstrap_external>", line 728, in exec_module
  File "<frozen importlib._bootstrap>", line 219, in _call_with_frames_removed
  File "/opt/airflow/dags/weather_data_dag.py", line 9, in <module>
    from weather_etl import WeatherPipeline
ModuleNotFoundError: No module named 'weather_etl'
[2023-08-11T08:16:15.965+0000] {processor.py:838} WARNING - No viable dags retrieved from /opt/airflow/dags/weather_data_dag.py
[2023-08-11T08:16:15.997+0000] {processor.py:179} INFO - Processing /opt/airflow/dags/weather_data_dag.py took 0.054 seconds
[2023-08-11T08:16:46.350+0000] {processor.py:157} INFO - Started process (PID=3193) to work on /opt/airflow/dags/weather_data_dag.py
[2023-08-11T08:16:46.351+0000] {processor.py:826} INFO - Processing file /opt/airflow/dags/weather_data_dag.py for tasks to queue
[2023-08-11T08:16:46.353+0000] {logging_mixin.py:150} INFO - [2023-08-11T08:16:46.352+0000] {dagbag.py:541} INFO - Filling up the DagBag from /opt/airflow/dags/weather_data_dag.py
[2023-08-11T08:16:46.361+0000] {logging_mixin.py:150} INFO - [2023-08-11T08:16:46.361+0000] {dagbag.py:350} ERROR - Failed to import: /opt/airflow/dags/weather_data_dag.py
Traceback (most recent call last):
  File "/home/airflow/.local/lib/python3.7/site-packages/airflow/models/dagbag.py", line 346, in parse
    loader.exec_module(new_module)
  File "<frozen importlib._bootstrap_external>", line 728, in exec_module
  File "<frozen importlib._bootstrap>", line 219, in _call_with_frames_removed
  File "/opt/airflow/dags/weather_data_dag.py", line 9, in <module>
    from weather_etl import WeatherPipeline
ModuleNotFoundError: No module named 'weather_etl'
[2023-08-11T08:16:46.361+0000] {processor.py:838} WARNING - No viable dags retrieved from /opt/airflow/dags/weather_data_dag.py
[2023-08-11T08:16:46.386+0000] {processor.py:179} INFO - Processing /opt/airflow/dags/weather_data_dag.py took 0.039 seconds
[2023-08-11T08:17:13.453+0000] {processor.py:157} INFO - Started process (PID=3253) to work on /opt/airflow/dags/weather_data_dag.py
[2023-08-11T08:17:13.454+0000] {processor.py:826} INFO - Processing file /opt/airflow/dags/weather_data_dag.py for tasks to queue
[2023-08-11T08:17:13.455+0000] {logging_mixin.py:150} INFO - [2023-08-11T08:17:13.455+0000] {dagbag.py:541} INFO - Filling up the DagBag from /opt/airflow/dags/weather_data_dag.py
[2023-08-11T08:17:14.313+0000] {logging_mixin.py:150} INFO - [2023-08-11T08:17:14.311+0000] {dagbag.py:350} ERROR - Failed to import: /opt/airflow/dags/weather_data_dag.py
Traceback (most recent call last):
  File "/home/airflow/.local/lib/python3.7/site-packages/airflow/models/dagbag.py", line 346, in parse
    loader.exec_module(new_module)
  File "<frozen importlib._bootstrap_external>", line 728, in exec_module
  File "<frozen importlib._bootstrap>", line 219, in _call_with_frames_removed
  File "/opt/airflow/dags/weather_data_dag.py", line 8, in <module>
    from weather_etl import WeatherPipeline
  File "/opt/airflow/dags/weather_etl.py", line 9, in <module>
    import awswrangler as wr
ModuleNotFoundError: No module named 'awswrangler'
[2023-08-11T08:17:14.313+0000] {processor.py:838} WARNING - No viable dags retrieved from /opt/airflow/dags/weather_data_dag.py
[2023-08-11T08:17:14.330+0000] {processor.py:179} INFO - Processing /opt/airflow/dags/weather_data_dag.py took 0.880 seconds
[2023-08-11T08:17:45.177+0000] {processor.py:157} INFO - Started process (PID=3342) to work on /opt/airflow/dags/weather_data_dag.py
[2023-08-11T08:17:45.179+0000] {processor.py:826} INFO - Processing file /opt/airflow/dags/weather_data_dag.py for tasks to queue
[2023-08-11T08:17:45.181+0000] {logging_mixin.py:150} INFO - [2023-08-11T08:17:45.180+0000] {dagbag.py:541} INFO - Filling up the DagBag from /opt/airflow/dags/weather_data_dag.py
[2023-08-11T08:17:47.187+0000] {logging_mixin.py:150} INFO - [2023-08-11T08:17:47.186+0000] {dagbag.py:350} ERROR - Failed to import: /opt/airflow/dags/weather_data_dag.py
Traceback (most recent call last):
  File "/home/airflow/.local/lib/python3.7/site-packages/airflow/models/dagbag.py", line 346, in parse
    loader.exec_module(new_module)
  File "<frozen importlib._bootstrap_external>", line 728, in exec_module
  File "<frozen importlib._bootstrap>", line 219, in _call_with_frames_removed
  File "/opt/airflow/dags/weather_data_dag.py", line 8, in <module>
    from weather_etl import WeatherPipeline
  File "/opt/airflow/dags/weather_etl.py", line 9, in <module>
    import awswrangler as wr
ModuleNotFoundError: No module named 'awswrangler'
[2023-08-11T08:17:47.188+0000] {processor.py:838} WARNING - No viable dags retrieved from /opt/airflow/dags/weather_data_dag.py
[2023-08-11T08:17:47.210+0000] {processor.py:179} INFO - Processing /opt/airflow/dags/weather_data_dag.py took 2.048 seconds
[2023-08-11T08:18:16.246+0000] {processor.py:157} INFO - Started process (PID=3422) to work on /opt/airflow/dags/weather_data_dag.py
[2023-08-11T08:18:16.248+0000] {processor.py:826} INFO - Processing file /opt/airflow/dags/weather_data_dag.py for tasks to queue
[2023-08-11T08:18:16.249+0000] {logging_mixin.py:150} INFO - [2023-08-11T08:18:16.249+0000] {dagbag.py:541} INFO - Filling up the DagBag from /opt/airflow/dags/weather_data_dag.py
[2023-08-11T08:18:17.754+0000] {logging_mixin.py:150} INFO - [2023-08-11T08:18:17.752+0000] {dagbag.py:350} ERROR - Failed to import: /opt/airflow/dags/weather_data_dag.py
Traceback (most recent call last):
  File "/home/airflow/.local/lib/python3.7/site-packages/airflow/models/dagbag.py", line 346, in parse
    loader.exec_module(new_module)
  File "<frozen importlib._bootstrap_external>", line 728, in exec_module
  File "<frozen importlib._bootstrap>", line 219, in _call_with_frames_removed
  File "/opt/airflow/dags/weather_data_dag.py", line 8, in <module>
    from weather_etl import WeatherPipeline
  File "/opt/airflow/dags/weather_etl.py", line 10, in <module>
    from xgboost import XGBRegressor
ModuleNotFoundError: No module named 'xgboost'
[2023-08-11T08:18:17.754+0000] {processor.py:838} WARNING - No viable dags retrieved from /opt/airflow/dags/weather_data_dag.py
[2023-08-11T08:18:17.780+0000] {processor.py:179} INFO - Processing /opt/airflow/dags/weather_data_dag.py took 1.539 seconds
[2023-08-11T08:18:48.403+0000] {processor.py:157} INFO - Started process (PID=3509) to work on /opt/airflow/dags/weather_data_dag.py
[2023-08-11T08:18:48.405+0000] {processor.py:826} INFO - Processing file /opt/airflow/dags/weather_data_dag.py for tasks to queue
[2023-08-11T08:18:48.410+0000] {logging_mixin.py:150} INFO - [2023-08-11T08:18:48.408+0000] {dagbag.py:541} INFO - Filling up the DagBag from /opt/airflow/dags/weather_data_dag.py
[2023-08-11T08:18:51.910+0000] {logging_mixin.py:150} INFO - [2023-08-11T08:18:51.899+0000] {dagbag.py:350} ERROR - Failed to import: /opt/airflow/dags/weather_data_dag.py
Traceback (most recent call last):
  File "/home/airflow/.local/lib/python3.7/site-packages/airflow/models/dagbag.py", line 346, in parse
    loader.exec_module(new_module)
  File "<frozen importlib._bootstrap_external>", line 728, in exec_module
  File "<frozen importlib._bootstrap>", line 219, in _call_with_frames_removed
  File "/opt/airflow/dags/weather_data_dag.py", line 8, in <module>
    from weather_etl import WeatherPipeline
  File "/opt/airflow/dags/weather_etl.py", line 10, in <module>
    from xgboost import XGBRegressor
ModuleNotFoundError: No module named 'xgboost'
[2023-08-11T08:18:51.911+0000] {processor.py:838} WARNING - No viable dags retrieved from /opt/airflow/dags/weather_data_dag.py
[2023-08-11T08:18:51.953+0000] {processor.py:179} INFO - Processing /opt/airflow/dags/weather_data_dag.py took 3.565 seconds
[2023-08-11T08:19:22.420+0000] {processor.py:157} INFO - Started process (PID=3592) to work on /opt/airflow/dags/weather_data_dag.py
[2023-08-11T08:19:22.422+0000] {processor.py:826} INFO - Processing file /opt/airflow/dags/weather_data_dag.py for tasks to queue
[2023-08-11T08:19:22.423+0000] {logging_mixin.py:150} INFO - [2023-08-11T08:19:22.422+0000] {dagbag.py:541} INFO - Filling up the DagBag from /opt/airflow/dags/weather_data_dag.py
[2023-08-11T08:19:23.126+0000] {logging_mixin.py:150} INFO - [2023-08-11T08:19:23.125+0000] {dagbag.py:350} ERROR - Failed to import: /opt/airflow/dags/weather_data_dag.py
Traceback (most recent call last):
  File "/home/airflow/.local/lib/python3.7/site-packages/airflow/models/dagbag.py", line 346, in parse
    loader.exec_module(new_module)
  File "<frozen importlib._bootstrap_external>", line 728, in exec_module
  File "<frozen importlib._bootstrap>", line 219, in _call_with_frames_removed
  File "/opt/airflow/dags/weather_data_dag.py", line 8, in <module>
    from weather_etl import WeatherPipeline
  File "/opt/airflow/dags/weather_etl.py", line 11, in <module>
    from sklearn.neural_network import MLPRegressor
ModuleNotFoundError: No module named 'sklearn'
[2023-08-11T08:19:23.127+0000] {processor.py:838} WARNING - No viable dags retrieved from /opt/airflow/dags/weather_data_dag.py
[2023-08-11T08:19:23.144+0000] {processor.py:179} INFO - Processing /opt/airflow/dags/weather_data_dag.py took 0.728 seconds
[2023-08-11T08:19:53.270+0000] {processor.py:157} INFO - Started process (PID=3676) to work on /opt/airflow/dags/weather_data_dag.py
[2023-08-11T08:19:53.271+0000] {processor.py:826} INFO - Processing file /opt/airflow/dags/weather_data_dag.py for tasks to queue
[2023-08-11T08:19:53.279+0000] {logging_mixin.py:150} INFO - [2023-08-11T08:19:53.271+0000] {dagbag.py:541} INFO - Filling up the DagBag from /opt/airflow/dags/weather_data_dag.py
[2023-08-11T08:19:54.311+0000] {logging_mixin.py:150} INFO - [2023-08-11T08:19:54.310+0000] {dagbag.py:350} ERROR - Failed to import: /opt/airflow/dags/weather_data_dag.py
Traceback (most recent call last):
  File "/home/airflow/.local/lib/python3.7/site-packages/airflow/models/dagbag.py", line 346, in parse
    loader.exec_module(new_module)
  File "<frozen importlib._bootstrap_external>", line 728, in exec_module
  File "<frozen importlib._bootstrap>", line 219, in _call_with_frames_removed
  File "/opt/airflow/dags/weather_data_dag.py", line 8, in <module>
    from weather_etl import WeatherPipeline
  File "/opt/airflow/dags/weather_etl.py", line 11, in <module>
    from sklearn.neural_network import MLPRegressor
ModuleNotFoundError: No module named 'sklearn'
[2023-08-11T08:19:54.311+0000] {processor.py:838} WARNING - No viable dags retrieved from /opt/airflow/dags/weather_data_dag.py
[2023-08-11T08:19:54.329+0000] {processor.py:179} INFO - Processing /opt/airflow/dags/weather_data_dag.py took 1.062 seconds
[2023-08-11T08:20:24.909+0000] {processor.py:157} INFO - Started process (PID=3762) to work on /opt/airflow/dags/weather_data_dag.py
[2023-08-11T08:20:24.910+0000] {processor.py:826} INFO - Processing file /opt/airflow/dags/weather_data_dag.py for tasks to queue
[2023-08-11T08:20:24.913+0000] {logging_mixin.py:150} INFO - [2023-08-11T08:20:24.912+0000] {dagbag.py:541} INFO - Filling up the DagBag from /opt/airflow/dags/weather_data_dag.py
[2023-08-11T08:20:26.447+0000] {logging_mixin.py:150} INFO - [2023-08-11T08:20:26.444+0000] {dagbag.py:350} ERROR - Failed to import: /opt/airflow/dags/weather_data_dag.py
Traceback (most recent call last):
  File "/home/airflow/.local/lib/python3.7/site-packages/airflow/models/dagbag.py", line 346, in parse
    loader.exec_module(new_module)
  File "<frozen importlib._bootstrap_external>", line 728, in exec_module
  File "<frozen importlib._bootstrap>", line 219, in _call_with_frames_removed
  File "/opt/airflow/dags/weather_data_dag.py", line 12, in <module>
    weather = WeatherPipline(locations)
NameError: name 'WeatherPipline' is not defined
[2023-08-11T08:20:26.447+0000] {processor.py:838} WARNING - No viable dags retrieved from /opt/airflow/dags/weather_data_dag.py
[2023-08-11T08:20:26.476+0000] {processor.py:179} INFO - Processing /opt/airflow/dags/weather_data_dag.py took 1.571 seconds
[2023-08-11T08:20:45.680+0000] {processor.py:157} INFO - Started process (PID=3808) to work on /opt/airflow/dags/weather_data_dag.py
[2023-08-11T08:20:45.682+0000] {processor.py:826} INFO - Processing file /opt/airflow/dags/weather_data_dag.py for tasks to queue
[2023-08-11T08:20:45.683+0000] {logging_mixin.py:150} INFO - [2023-08-11T08:20:45.682+0000] {dagbag.py:541} INFO - Filling up the DagBag from /opt/airflow/dags/weather_data_dag.py
[2023-08-11T08:20:47.206+0000] {processor.py:836} INFO - DAG(s) dict_keys(['load_weather_data']) retrieved from /opt/airflow/dags/weather_data_dag.py
[2023-08-11T08:20:47.365+0000] {logging_mixin.py:150} INFO - [2023-08-11T08:20:47.365+0000] {manager.py:504} INFO - Created Permission View: can delete on DAG:load_weather_data
[2023-08-11T08:20:47.386+0000] {logging_mixin.py:150} INFO - [2023-08-11T08:20:47.385+0000] {manager.py:504} INFO - Created Permission View: can edit on DAG:load_weather_data
[2023-08-11T08:20:47.397+0000] {logging_mixin.py:150} INFO - [2023-08-11T08:20:47.397+0000] {manager.py:504} INFO - Created Permission View: can read on DAG:load_weather_data
[2023-08-11T08:20:47.420+0000] {logging_mixin.py:150} INFO - [2023-08-11T08:20:47.419+0000] {dag.py:2742} INFO - Sync 1 DAGs
[2023-08-11T08:20:47.440+0000] {logging_mixin.py:150} INFO - [2023-08-11T08:20:47.440+0000] {dag.py:2763} INFO - Creating ORM DAG for load_weather_data
[2023-08-11T08:20:47.462+0000] {logging_mixin.py:150} INFO - [2023-08-11T08:20:47.461+0000] {dag.py:3508} INFO - Setting next_dagrun for load_weather_data to 2023-08-12T00:00:00+00:00, run_after=2023-08-13T00:00:00+00:00
[2023-08-11T08:20:47.503+0000] {processor.py:179} INFO - Processing /opt/airflow/dags/weather_data_dag.py took 1.826 seconds
[2023-08-11T08:20:51.342+0000] {processor.py:157} INFO - Started process (PID=3829) to work on /opt/airflow/dags/weather_data_dag.py
[2023-08-11T08:20:51.342+0000] {processor.py:826} INFO - Processing file /opt/airflow/dags/weather_data_dag.py for tasks to queue
[2023-08-11T08:20:51.343+0000] {logging_mixin.py:150} INFO - [2023-08-11T08:20:51.343+0000] {dagbag.py:541} INFO - Filling up the DagBag from /opt/airflow/dags/weather_data_dag.py
[2023-08-11T08:20:52.734+0000] {processor.py:836} INFO - DAG(s) dict_keys(['load_weather_data']) retrieved from /opt/airflow/dags/weather_data_dag.py
[2023-08-11T08:20:52.750+0000] {logging_mixin.py:150} INFO - [2023-08-11T08:20:52.749+0000] {dag.py:2742} INFO - Sync 1 DAGs
[2023-08-11T08:20:52.776+0000] {logging_mixin.py:150} INFO - [2023-08-11T08:20:52.776+0000] {dag.py:3508} INFO - Setting next_dagrun for load_weather_data to 2023-08-12T00:00:00+00:00, run_after=2023-08-13T00:00:00+00:00
[2023-08-11T08:20:52.804+0000] {processor.py:179} INFO - Processing /opt/airflow/dags/weather_data_dag.py took 1.465 seconds
[2023-08-11T08:21:20.420+0000] {processor.py:157} INFO - Started process (PID=3906) to work on /opt/airflow/dags/weather_data_dag.py
[2023-08-11T08:21:20.423+0000] {processor.py:826} INFO - Processing file /opt/airflow/dags/weather_data_dag.py for tasks to queue
[2023-08-11T08:21:20.425+0000] {logging_mixin.py:150} INFO - [2023-08-11T08:21:20.425+0000] {dagbag.py:541} INFO - Filling up the DagBag from /opt/airflow/dags/weather_data_dag.py
[2023-08-11T08:21:21.885+0000] {processor.py:836} INFO - DAG(s) dict_keys(['load_weather_data']) retrieved from /opt/airflow/dags/weather_data_dag.py
[2023-08-11T08:21:21.909+0000] {logging_mixin.py:150} INFO - [2023-08-11T08:21:21.909+0000] {dag.py:2742} INFO - Sync 1 DAGs
[2023-08-11T08:21:21.942+0000] {logging_mixin.py:150} INFO - [2023-08-11T08:21:21.940+0000] {dag.py:3508} INFO - Setting next_dagrun for load_weather_data to 2023-08-12T00:00:00+00:00, run_after=2023-08-13T00:00:00+00:00
[2023-08-11T08:21:21.973+0000] {processor.py:179} INFO - Processing /opt/airflow/dags/weather_data_dag.py took 1.556 seconds
[2023-08-11T08:21:27.010+0000] {processor.py:157} INFO - Started process (PID=3949) to work on /opt/airflow/dags/weather_data_dag.py
[2023-08-11T08:21:27.011+0000] {processor.py:826} INFO - Processing file /opt/airflow/dags/weather_data_dag.py for tasks to queue
[2023-08-11T08:21:27.012+0000] {logging_mixin.py:150} INFO - [2023-08-11T08:21:27.012+0000] {dagbag.py:541} INFO - Filling up the DagBag from /opt/airflow/dags/weather_data_dag.py
[2023-08-11T08:21:28.190+0000] {processor.py:836} INFO - DAG(s) dict_keys(['load_weather_data']) retrieved from /opt/airflow/dags/weather_data_dag.py
[2023-08-11T08:21:28.210+0000] {logging_mixin.py:150} INFO - [2023-08-11T08:21:28.209+0000] {dag.py:2742} INFO - Sync 1 DAGs
[2023-08-11T08:21:28.233+0000] {logging_mixin.py:150} INFO - [2023-08-11T08:21:28.233+0000] {dag.py:3508} INFO - Setting next_dagrun for load_weather_data to 2023-08-12T00:00:00+00:00, run_after=2023-08-13T00:00:00+00:00
[2023-08-11T08:21:28.253+0000] {processor.py:179} INFO - Processing /opt/airflow/dags/weather_data_dag.py took 1.246 seconds
[2023-08-11T08:21:49.537+0000] {processor.py:157} INFO - Started process (PID=3995) to work on /opt/airflow/dags/weather_data_dag.py
[2023-08-11T08:21:49.538+0000] {processor.py:826} INFO - Processing file /opt/airflow/dags/weather_data_dag.py for tasks to queue
[2023-08-11T08:21:49.539+0000] {logging_mixin.py:150} INFO - [2023-08-11T08:21:49.538+0000] {dagbag.py:541} INFO - Filling up the DagBag from /opt/airflow/dags/weather_data_dag.py
[2023-08-11T08:21:51.252+0000] {processor.py:836} INFO - DAG(s) dict_keys(['load_weather_data']) retrieved from /opt/airflow/dags/weather_data_dag.py
[2023-08-11T08:21:51.280+0000] {logging_mixin.py:150} INFO - [2023-08-11T08:21:51.279+0000] {dag.py:2742} INFO - Sync 1 DAGs
[2023-08-11T08:21:51.312+0000] {logging_mixin.py:150} INFO - [2023-08-11T08:21:51.312+0000] {dag.py:3508} INFO - Setting next_dagrun for load_weather_data to 2023-08-12T00:00:00+00:00, run_after=2023-08-13T00:00:00+00:00
[2023-08-11T08:21:51.338+0000] {processor.py:179} INFO - Processing /opt/airflow/dags/weather_data_dag.py took 1.806 seconds
[2023-08-11T08:21:55.869+0000] {processor.py:157} INFO - Started process (PID=4035) to work on /opt/airflow/dags/weather_data_dag.py
[2023-08-11T08:21:55.870+0000] {processor.py:826} INFO - Processing file /opt/airflow/dags/weather_data_dag.py for tasks to queue
[2023-08-11T08:21:55.871+0000] {logging_mixin.py:150} INFO - [2023-08-11T08:21:55.871+0000] {dagbag.py:541} INFO - Filling up the DagBag from /opt/airflow/dags/weather_data_dag.py
[2023-08-11T08:21:57.259+0000] {processor.py:836} INFO - DAG(s) dict_keys(['load_weather_data']) retrieved from /opt/airflow/dags/weather_data_dag.py
[2023-08-11T08:21:57.283+0000] {logging_mixin.py:150} INFO - [2023-08-11T08:21:57.282+0000] {dag.py:2742} INFO - Sync 1 DAGs
[2023-08-11T08:21:57.307+0000] {logging_mixin.py:150} INFO - [2023-08-11T08:21:57.306+0000] {dag.py:3508} INFO - Setting next_dagrun for load_weather_data to 2023-08-12T00:00:00+00:00, run_after=2023-08-13T00:00:00+00:00
[2023-08-11T08:21:57.329+0000] {processor.py:179} INFO - Processing /opt/airflow/dags/weather_data_dag.py took 1.463 seconds
[2023-08-11T08:22:28.141+0000] {processor.py:157} INFO - Started process (PID=4118) to work on /opt/airflow/dags/weather_data_dag.py
[2023-08-11T08:22:28.141+0000] {processor.py:826} INFO - Processing file /opt/airflow/dags/weather_data_dag.py for tasks to queue
[2023-08-11T08:22:28.142+0000] {logging_mixin.py:150} INFO - [2023-08-11T08:22:28.142+0000] {dagbag.py:541} INFO - Filling up the DagBag from /opt/airflow/dags/weather_data_dag.py
